Workbook

Sheet SHARED_VARIABLES
B1: B I T C O I N L I G H T N I N G C R E D I T D E R I V A T I V E S - S H A R E D V A R I A B L E S
B2: A global, permissionless, decentralized and distributed strategy for ultra-high yields using leveraged bitcoin growth, liquidity and transaction leasing exposure
B4: A M P L I F Y Y O U R B I T C O I N O N T H E L I G H T N I N G N E T W O R K | D4: B I T C O I N L E A S I N G Y I E L D A N N U A L I Z E D F I A T O R B T C | H4: G R O W T H | L4: L I Q U I D I T Y | P4: T R A N S A C T I O N
H5: 0.3 | L5: 0.01 | P5: 0.005
D7: B I T C O I N L E A S I N G F E E S A N N U A L I Z E D F I A T | H7: S E C U R I T Y | L7: D E B T | P7: S E R V I C E
H8: 0.115 | L8: 0.075 | P8: 0.05
B10: C A P I T A L L E V E R A G E | F10: 2 X | H10: 2 . 5 X | J10: 3 X | L10: 3 . 5 X | N10: 4 X | P10: 4 . 5 X | R10: 5 X
B11: L E A S E - T O - C A P I T A L | D11: S E C U R I T Y | F11: 1 | H11: 1 | J11: 1 | L11: 1 | N11: 1 | P11: 1 | R11: 1
D12: D E B T | F12: 0 | H12: 0.5 | J12: 1 | L12: 1.5 | N12: 2 | P12: 2.5 | R12: 3
D13: T O T A L | F13: =SUM(F11:F12) -> 1 | G13: =SUM(G11:G12) -> 0 | H13: =SUM(H11:H12) -> 1.5 | I13: =SUM(I11:I12) -> 0 | J13: =SUM(J11:J12) -> 2 | K13: =SUM(K11:K12) -> 0 | L13: =SUM(L11:L12) -> 2.5 | M13: =SUM(M11:M12) -> 0 | ... R13: =SUM(R11:R12) -> 4
C14: P O S I T I O N | F14: D E S C R I P T I O N | N14: B U Y S | P14: R E C E I V E S
B15: M E E T T H E P L A Y E R S | C15: Bitcoin Borrower | F15: Self-custodial bitcoin capital with price drawdown liquidation protection | N15: Bitcoin | P15: Net Total Bitcoin Yield
C16: Fiat Lender | F16: Custodial bitcoin credit with fiat price stability | N16: Security (ex: ETF) | P16: Security Fees
C17: Lightning Service Provider | F17: Balancer providing bitcoin yield collection and distribution services | N17: Bitcoin | P17: Debt and Service Fees

Sheet BORROWER_YIELD
B1: B I T C O I N L I G H T N I N G C R E D I T D E R I V A T I V E S - B I T C O I N B O R R O W E R Y I E L D S U M M A R Y | R1: X: @KyleHutch_
B2: A global, permissionless, decentralized and distributed strategy for ultra-high yields using leveraged bitcoin growth, liquidity and transaction leasing exposure | R2: 46087
B4: A M P L I F Y Y O U R B I T C O I N O N T H E L I G H T N I N G N E T W O R K | D4: B I T C O I N L E A S I N G Y I E L D A N N U A L I Z E D F I A T O R B T C | H4: G R O W T H | L4: L I Q U I D I T Y | P4: T R A N S A C T I O N
H5: =SHARED_VARIABLES!H5 -> 0.3 | L5: =SHARED_VARIABLES!L5 -> 0.01 | P5: =SHARED_VARIABLES!P5 -> 0.005
D7: B I T C O I N L E A S I N G F E E S A N N U A L I Z E D F I A T | H7: S E C U R I T Y | L7: D E B T | P7: S E R V I C E
H8: =SHARED_VARIABLES!H8 -> 0.115 | L8: =SHARED_VARIABLES!L8 -> 0.075 | P8: =SHARED_VARIABLES!P8 -> 0.05
B10: C A P I T A L L E V E R A G E | F10: 2 X | H10: 2 . 5 X | J10: 3 X | L10: 3 . 5 X | N10: 4 X | P10: 4 . 5 X | R10: 5 X
B11: L E A S E - T O - C A P I T A L | D11: S E C U R I T Y | F11: 1 | H11: 1 | J11: 1 | L11: 1 | N11: 1 | P11: 1 | R11: 1
D12: D E B T | F12: 0 | H12: 0.5 | J12: 1 | L12: 1.5 | N12: 2 | P12: 2.5 | R12: 3
D13: T O T A L | F13: =SUM(F11:F12) -> 1 | G13: =SUM(G11:G12) -> 0 | H13: =SUM(H11:H12) -> 1.5 | I13: =SUM(I11:I12) -> 0 | J13: =SUM(J11:J12) -> 2 | K13: =SUM(K11:K12) -> 0 | L13: =SUM(L11:L12) -> 2.5 | M13: =SUM(M11:M12) -> 0 | ... R13: =SUM(R11:R12) -> 4
B14: B I T C O I N L E A S I N G Y I E L D A N N U A L I Z E D B T C 5 Y E A R A V E R A G E | D14: G R O W T H | F14: =AVERAGE('2X'!E16:I16) -> 0.14613419 | H14: =AVERAGE('2.5X'!E16:I16) -> 0.21920128 | J14: =AVERAGE('3X'!E16:I16) -> 0.29226837 | L14: =AVERAGE('3.5X'!E16:I16) -> 0.36533546 | N14: =AVERAGE('4X'!E16:I16) -> 0.43840256 | P14: =AVERAGE('4.5X'!E16:I16) -> 0.51146965 | R14: =AVERAGE('5X'!E16:I16) -> 0.58453674
D15: L I Q U I D I T Y | F15: =AVERAGE('2X'!E17:I17) -> 0.01487114 | H15: =AVERAGE('2.5X'!E17:I17) -> 0.01987114 | J15: =AVERAGE('3X'!E17:I17) -> 0.02487114 | L15: =AVERAGE('3.5X'!E17:I17) -> 0.02987114 | N15: =AVERAGE('4X'!E17:I17) -> 0.03487114 | P15: =AVERAGE('4.5X'!E17:I17) -> 0.03987114 | R15: =AVERAGE('5X'!E17:I17) -> 0.04487114
D16: T R A N S A C T I O N | F16: =AVERAGE('2X'!E18:I18) -> 0.0074355698 | H16: =AVERAGE('2.5X'!E18:I18) -> 0.0099355698 | J16: =AVERAGE('3X'!E18:I18) -> 0.01243557 | L16: =AVERAGE('3.5X'!E18:I18) -> 0.01493557 | N16: =AVERAGE('4X'!E18:I18) -> 0.01743557 | P16: =AVERAGE('4.5X'!E18:I18) -> 0.01993557 | R16: =AVERAGE('5X'!E18:I18) -> 0.02243557
D17: G R O S S T O T A L | F17: =SUM(F14:F16) -> 0.16844089 | H17: =SUM(H14:H16) -> 0.24900799 | J17: =SUM(J14:J16) -> 0.32957508 | L17: =SUM(L14:L16) -> 0.41014217 | N17: =SUM(N14:N16) -> 0.49070926 | P17: =SUM(P14:P16) -> 0.57127636 | R17: =SUM(R14:R16) -> 0.65184345
D18: N E T T O T A L | F18: =AVERAGE('2X'!E20:I20) -> 0.088067093 | H18: =AVERAGE('2.5X'!E20:I20) -> 0.13818956 | J18: =AVERAGE('3X'!E20:I20) -> 0.18831203 | L18: =AVERAGE('3.5X'!E20:I20) -> 0.2384345 | N18: =AVERAGE('4X'!E20:I20) -> 0.28855698 | P18: =AVERAGE('4.5X'!E20:I20) -> 0.33867945 | R18: =AVERAGE('5X'!E20:I20) -> 0.38880192
D19: A M P L I F I E D C A G R | F19: =$H$5 + F18 + (F18 * $H$5) -> 0.41448722 | H19: =$H$5 + H18 + (H18 * $H$5) -> 0.47964643 | J19: =$H$5 + J18 + (J18 * $H$5) -> 0.54480564 | L19: =$H$5 + L18 + (L18 * $H$5) -> 0.60996486 | N19: =$H$5 + N18 + (N18 * $H$5) -> 0.67512407 | P19: =$H$5 + P18 + (P18 * $H$5) -> 0.74028328 | R19: =$H$5 + R18 + (R18 * $H$5) -> 0.80544249
B20: B I T C O I N L E A S I N G Y I E L D A N N U A L I Z E D B T C 10 Y E A R A V E R A G E | D20: G R O W T H | F20: =AVERAGE('2X'!E16:N16) -> 0.092746185 | H20: =AVERAGE('2.5X'!E16:N16) -> 0.13911928 | J20: =AVERAGE('3X'!E16:N16) -> 0.18549237 | L20: =AVERAGE('3.5X'!E16:N16) -> 0.23186546 | N20: =AVERAGE('4X'!E16:N16) -> 0.27823855 | P20: =AVERAGE('4.5X'!E16:N16) -> 0.32461165 | R20: =AVERAGE('5X'!E16:N16) -> 0.37098474
D21: L I Q U I D I T Y | F21: =AVERAGE('2X'!E17:N17) -> 0.013091539 | H21: =AVERAGE('2.5X'!E17:N17) -> 0.018091539 | J21: =AVERAGE('3X'!E17:N17) -> 0.023091539 | L21: =AVERAGE('3.5X'!E17:N17) -> 0.028091539 | N21: =AVERAGE('4X'!E17:N17) -> 0.033091539 | P21: =AVERAGE('4.5X'!E17:N17) -> 0.038091539 | R21: =AVERAGE('5X'!E17:N17) -> 0.043091539
D22: T R A N S A C T I O N | F22: =AVERAGE('2X'!E18:N18) -> 0.0065457697 | H22: =AVERAGE('2.5X'!E18:N18) -> 0.0090457697 | J22: =AVERAGE('3X'!E18:N18) -> 0.01154577 | L22: =AVERAGE('3.5X'!E18:N18) -> 0.01404577 | N22: =AVERAGE('4X'!E18:N18) -> 0.01654577 | P22: =AVERAGE('4.5X'!E18:N18) -> 0.01904577 | R22: =AVERAGE('5X'!E18:N18) -> 0.02154577
D23: G R O S S T O T A L | F23: =SUM(F20:F22) -> 0.11238349 | H23: =SUM(H20:H22) -> 0.16625659 | J23: =SUM(J20:J22) -> 0.22012968 | L23: =SUM(L20:L22) -> 0.27400277 | N23: =SUM(N20:N22) -> 0.32787586 | P23: =SUM(P20:P22) -> 0.38174896 | R23: =SUM(R20:R22) -> 0.43562205
D24: N E T T O T A L | F24: =AVERAGE('2X'!E20:N20) -> 0.061373092 | H24: =AVERAGE('2.5X'!E20:N20) -> 0.095924063 | J24: =AVERAGE('3X'!E20:N20) -> 0.13047503 | L24: =AVERAGE('3.5X'!E20:N20) -> 0.165026 | N24: =AVERAGE('4X'!E20:N20) -> 0.19957697 | P24: =AVERAGE('4.5X'!E20:N20) -> 0.23412795 | R24: =AVERAGE('5X'!E20:N20) -> 0.26867892
D25: A M P L I F I E D C A G R | F25: =$H$5 + F24 + (F24 * $H$5) -> 0.37978502 | H25: =$H$5 + H24 + (H24 * $H$5) -> 0.42470128 | J25: =$H$5 + J24 + (J24 * $H$5) -> 0.46961754 | L25: =$H$5 + L24 + (L24 * $H$5) -> 0.51453381 | N25: =$H$5 + N24 + (N24 * $H$5) -> 0.55945007 | P25: =$H$5 + P24 + (P24 * $H$5) -> 0.60436633 | R25: =$H$5 + R24 + (R24 * $H$5) -> 0.64928259
C26: P O S I T I O N | F26: D E S C R I P T I O N | N26: B U Y S | P26: R E C E I V E S
B27: M E E T T H E P L A Y E R S | C27: Bitcoin Borrower | F27: Self-custodial bitcoin capital with price drawdown liquidation protection | N27: Bitcoin | P27: Net Total Bitcoin Yield
C28: Fiat Lender | F28: Custodial bitcoin credit with fiat price stability | N28: Security (ex: ETF) | P28: Security Fees
C29: Lightning Service Provider | F29: Balancer providing bitcoin yield collection and distribution services | N29: Bitcoin | P29: Debt and Service Fees

Sheet LSP_REVENUE
B1: B I T C O I N L I G H T N I N G C R E D I T D E R I V A T I V E S - L S P R E V E N U E S U M M A R Y | R1: X: @KyleHutch_
B2: A global, permissionless, decentralized and distributed strategy for ultra-high yields using leveraged bitcoin growth, liquidity and transaction leasing exposure | R2: 46087
B4: A M P L I F Y Y O U R B I T C O I N O N T H E L I G H T N I N G N E T W O R K | D4: B I T C O I N L E A S I N G Y I E L D A N N U A L I Z E D F I A T O R B T C | H4: G R O W T H | L4: L I Q U I D I T Y | P4: T R A N S A C T I O N
H5: =SHARED_VARIABLES!H5 -> 0.3 | L5: =SHARED_VARIABLES!L5 -> 0.01 | P5: =SHARED_VARIABLES!P5 -> 0.005
D7: B I T C O I N L E A S I N G F E E S A N N U A L I Z E D F I A T | H7: S E C U R I T Y | L7: D E B T | P7: S E R V I C E
H8: =SHARED_VARIABLES!H8 -> 0.115 | L8: =SHARED_VARIABLES!L8 -> 0.075 | P8: =SHARED_VARIABLES!P8 -> 0.05
B10: C A P I T A L L E V E R A G E | F10: 2 X | H10: 2 . 5 X | J10: 3 X | L10: 3 . 5 X | N10: 4 X | P10: 4 . 5 X | R10: 5 X
B11: L E A S E - T O - C A P I T A L | D11: S E C U R I T Y | F11: 1 | H11: 1 | J11: 1 | L11: 1 | N11: 1 | P11: 1 | R11: 1
D12: D E B T | F12: 0 | H12: 0.5 | J12: 1 | L12: 1.5 | N12: 2 | P12: 2.5 | R12: 3
D13: T O T A L | F13: =SUM(F11:F12) -> 1 | G13: =SUM(G11:G12) -> 0 | H13: =SUM(H11:H12) -> 1.5 | I13: =SUM(I11:I12) -> 0 | J13: =SUM(J11:J12) -> 2 | K13: =SUM(K11:K12) -> 0 | L13: =SUM(L11:L12) -> 2.5 | M13: =SUM(M11:M12) -> 0 | ... R13: =SUM(R11:R12) -> 4
B14: B I T C O I N T V L R E V E N U E A N N U A L I Z E D B T C 5 Y E A R A V E R A G E | D14: S E R V I C E F E E | F14: =AVERAGE('2X'!E14:I14) -> 0.024355698 | H14: =AVERAGE('2.5X'!E14:I14) -> 0.036533546 | J14: =AVERAGE('3X'!E14:I14) -> 0.048711395 | L14: =AVERAGE('3.5X'!E14:I14) -> 0.060889244 | N14: =AVERAGE('4X'!E14:I14) -> 0.073067093 | P14: =AVERAGE('4.5X'!E14:I14) -> 0.085244941 | R14: =AVERAGE('5X'!E14:I14) -> 0.09742279
D15: 20000 | F15: =AVERAGE('2X'!E21:I21) -> 243.55698 | H15: =AVERAGE('2.5X'!E21:I21) -> 292.26837 | J15: =AVERAGE('3X'!E21:I21) -> 324.74263 | L15: =AVERAGE('3.5X'!E21:I21) -> 347.93854 | N15: =AVERAGE('4X'!E21:I21) -> 365.33546 | P15: =AVERAGE('4.5X'!E21:I21) -> 378.86641 | R15: =AVERAGE('5X'!E21:I21) -> 389.69116
D16: 400000 | F16: =AVERAGE('2X'!E22:I22) -> 4871.1395 | H16: =AVERAGE('2.5X'!E22:I22) -> 5845.3674 | J16: =AVERAGE('3X'!E22:I22) -> 6494.8527 | L16: =AVERAGE('3.5X'!E22:I22) -> 6958.7707 | N16: =AVERAGE('4X'!E22:I22) -> 7306.7093 | P16: =AVERAGE('4.5X'!E22:I22) -> 7577.3281 | R16: =AVERAGE('5X'!E22:I22) -> 7793.8232
D17: 1000000 | F17: =AVERAGE('2X'!E23:I23) -> 12177.849 | H17: =AVERAGE('2.5X'!E23:I23) -> 14613.419 | J17: =AVERAGE('3X'!E23:I23) -> 16237.132 | L17: =AVERAGE('3.5X'!E23:I23) -> 17396.927 | N17: =AVERAGE('4X'!E23:I23) -> 18266.773 | P17: =AVERAGE('4.5X'!E23:I23) -> 18943.32 | R17: =AVERAGE('5X'!E23:I23) -> 19484.558
D18: 2100000 | F18: =AVERAGE('2X'!E24:I24) -> 25573.482 | H18: =AVERAGE('2.5X'!E24:I24) -> 30688.179 | J18: =AVERAGE('3X'!E24:I24) -> 34097.977 | L18: =AVERAGE('3.5X'!E24:I24) -> 36533.546 | N18: =AVERAGE('4X'!E24:I24) -> 38360.224 | P18: =AVERAGE('4.5X'!E24:I24) -> 39780.973 | R18: =AVERAGE('5X'!E24:I24) -> 40917.572
B19: B I T C O I N T V L R E V E N U E A N N U A L I Z E D B T C 10 Y E A R A V E R A G E | D19: S E R V I C E F E E | F19: =AVERAGE('2X'!E14:N14) -> 0.015457697 | H19: =AVERAGE('2.5X'!E14:N14) -> 0.023186546 | J19: =AVERAGE('3X'!E14:N14) -> 0.030915395 | L19: =AVERAGE('3.5X'!E14:N14) -> 0.038644244 | N19: =AVERAGE('4X'!E14:N14) -> 0.046373092 | P19: =AVERAGE('4.5X'!E14:N14) -> 0.054101941 | R19: =AVERAGE('5X'!E14:N14) -> 0.06183079
D20: 20000 | F20: =AVERAGE('2X'!E21:N21) -> 154.57697 | H20: =AVERAGE('2.5X'!E21:N21) -> 185.49237 | J20: =AVERAGE('3X'!E21:N21) -> 206.10263 | L20: =AVERAGE('3.5X'!E21:N21) -> 220.82425 | N20: =AVERAGE('4X'!E21:N21) -> 231.86546 | P20: =AVERAGE('4.5X'!E21:N21) -> 240.45307 | R20: =AVERAGE('5X'!E21:N21) -> 247.32316
D21: 400000 | F21: =AVERAGE('2X'!E22:N22) -> 3091.5395 | H21: =AVERAGE('2.5X'!E22:N22) -> 3709.8474 | J21: =AVERAGE('3X'!E22:N22) -> 4122.0527 | L21: =AVERAGE('3.5X'!E22:N22) -> 4416.485 | N21: =AVERAGE('4X'!E22:N22) -> 4637.3092 | P21: =AVERAGE('4.5X'!E22:N22) -> 4809.0614 | R21: =AVERAGE('5X'!E22:N22) -> 4946.4632
D22: 1000000 | F22: =AVERAGE('2X'!E23:N23) -> 7728.8487 | H22: =AVERAGE('2.5X'!E23:N23) -> 9274.6185 | J22: =AVERAGE('3X'!E23:N23) -> 10305.132 | L22: =AVERAGE('3.5X'!E23:N23) -> 11041.212 | N22: =AVERAGE('4X'!E23:N23) -> 11593.273 | P22: =AVERAGE('4.5X'!E23:N23) -> 12022.654 | R22: =AVERAGE('5X'!E23:N23) -> 12366.158
D23: 2100000 | F23: =AVERAGE('2X'!E24:N24) -> 16230.582 | H23: =AVERAGE('2.5X'!E24:N24) -> 19476.699 | J23: =AVERAGE('3X'!E24:N24) -> 21640.776 | L23: =AVERAGE('3.5X'!E24:N24) -> 23186.546 | N23: =AVERAGE('4X'!E24:N24) -> 24345.874 | P23: =AVERAGE('4.5X'!E24:N24) -> 25247.573 | R23: =AVERAGE('5X'!E24:N24) -> 25968.932
C24: P O S I T I O N | F24: D E S C R I P T I O N | N24: B U Y S | P24: R E C E I V E S
B25: M E E T T H E P L A Y E R S | C25: Bitcoin Borrower | F25: Self-custodial bitcoin capital with price drawdown liquidation protection | N25: Bitcoin | P25: Net Total Bitcoin Yield
C26: Fiat Lender | F26: Custodial bitcoin credit with fiat price stability | N26: Security (ex: ETF) | P26: Security Fees
C27: Lightning Service Provider | F27: Balancer providing bitcoin yield collection and distribution services | N27: Bitcoin | P27: Debt and Service Fees

Sheet LENDER_YIELD
B1: B I T C O I N L I G H T N I N G C R E D I T D E R I V A T I V E S - L E N D E R Y I E L D S U M M A R Y
B3: A M P L I F Y Y O U R F I A T | C3: E X P E C T E D S E C U R I T Y Y I E L D A N N U A L I Z E D F I A T | G3: =SHARED_VARIABLES!H8 -> 0.115
E5: Security = Bond, Preferred Share, Exchange Traded Fund (ETF)

Sheet 2X
B2: A M P L I F Y Y O U R B I T C O I N O N T H E L I G H T N I N G N E T W O R K | C2: B I T C O I N L E A S I N G Y I E L D A N N U A L I Z E D F I A T O R B T C | E2: G R O W T H | H2: L I Q U I D I T Y | K2: T R A N S A C T I O N | N2: D E B T L E A S E T O C A P I T A L
E3: =SHARED_VARIABLES!H5 -> 0.3 | H3: =SHARED_VARIABLES!L5 -> 0.01 | K3: =SHARED_VARIABLES!P5 -> 0.005
C5: B I T C O I N L E A S I N G F E E S A N N U A L I Z E D F I A T | E5: S E C U R I T Y | H5: D E B T | K5: S E R V I C E
E6: =SHARED_VARIABLES!H8 -> 0.115 | H6: =SHARED_VARIABLES!L8 -> 0.075 | K6: =SHARED_VARIABLES!P8 -> 0.05 | N6: =SHARED_VARIABLES!F12 -> 0
E8: Y E A R 1 | F8: Y E A R 2 | G8: Y E A R 3 | H8: Y E A R 4 | I8: Y E A R 5 | J8: Y E A R 6 | K8: Y E A R 7 | L8: Y E A R 8 | M8: Y E A R 9 | N8: Y E A R 10
B9: B I T C O I N G R O W T H | C9: C U M U L A T I V E F I A T | E9: =$E$3 -> 0.3 | F9: =$E$3 + (E9 * $E$3) + E9 -> 0.69 | G9: =$E$3 + (F9 * $E$3) + F9 -> 1.197 | H9: =$E$3 + (G9 * $E$3) + G9 -> 1.8561 | I9: =$E$3 + (H9 * $E$3) + H9 -> 2.71293 | J9: =$E$3 + (I9 * $E$3) + I9 -> 3.826809 | K9: =$E$3 + (J9 * $E$3) + J9 -> 5.2748517 | L9: =$E$3 + (K9 * $E$3) + K9 -> 7.1573072 | M9: =$E$3 + (L9 * $E$3) + L9 -> 9.6044994 | N9: =$E$3 + (M9 * $E$3) + M9 -> 12.785849
B10: B I T CO I N E X T R A C T I O N | C10: C U M U L A T I V E B T C | E10: =((1 + E9) - 1) / (1 + E9) -> 0.23076923 | F10: =((1 + F9) - 1) / (1 + F9) -> 0.40828402 | G10: =((1 + G9) - 1) / (1 + G9) -> 0.54483386 | H10: =((1 + H9) - 1) / (1 + H9) -> 0.6498722 | I10: =((1 + I9) - 1) / (1 + I9) -> 0.73067093 | J10: =((1 + J9) - 1) / (1 + J9) -> 0.79282379 | K10: =((1 + K9) - 1) / (1 + K9) -> 0.84063368 | L10: =((1 + L9) - 1) / (1 + L9) -> 0.87741053 | ... N10: =((1 + N9) - 1) / (1 + N9) -> 0.92746185
C11: R E M A I N I N G B T C | E11: =1 - E10 -> 0.76923077 | F11: =1 - F10 -> 0.59171598 | G11: =1 - G10 -> 0.45516614 | H11: =1 - H10 -> 0.3501278 | I11: =1 - I10 -> 0.26932907 | J11: =1 - J10 -> 0.20717621 | K11: =1 - K10 -> 0.15936632 | L11: =1 - L10 -> 0.12258947 | ... N11: =1 - N10 -> 0.07253815
B12: B I T C O I N L E A S I N G F E E S A N N U A L I Z E D B T C | C12: S E C U R I T Y | E12: =$E$6 * E11 -> 0.088461538 | F12: =$E$6 * F11 -> 0.068047337 | G12: =$E$6 * G11 -> 0.052344106 | H12: =$E$6 * H11 -> 0.040264697 | I12: =$E$6 * I11 -> 0.030972844 | J12: =$E$6 * J11 -> 0.023825264 | K12: =$E$6 * K11 -> 0.018327126 | L12: =$E$6 * L11 -> 0.01409779 | ... N12: =$E$6 * N11 -> 0.0083418873
C13: D E B T | E13: =$H$6 * $N$6 * E11 -> 0 | F13: =$H$6 * $N$6 * F11 -> 0 | G13: =$H$6 * $N$6 * G11 -> 0 | H13: =$H$6 * $N$6 * H11 -> 0 | I13: =$H$6 * $N$6 * I11 -> 0 | J13: =$H$6 * $N$6 * J11 -> 0 | K13: =$H$6 * $N$6 * K11 -> 0 | L13: =$H$6 * $N$6 * L11 -> 0 | ... N13: =$H$6 * $N$6 * N11 -> 0
C14: S E R V I C E | E14: =($K$6 * E11) + ($K$6 * $N$6 * E11) -> 0.038461538 | F14: =($K$6 * F11) + ($K$6 * $N$6 * F11) -> 0.029585799 | G14: =($K$6 * G11) + ($K$6 * $N$6 * G11) -> 0.022758307 | H14: =($K$6 * H11) + ($K$6 * $N$6 * H11) -> 0.01750639 | I14: =($K$6 * I11) + ($K$6 * $N$6 * I11) -> 0.013466454 | J14: =($K$6 * J11) + ($K$6 * $N$6 * J11) -> 0.010358811 | K14: =($K$6 * K11) + ($K$6 * $N$6 * K11) -> 0.0079683158 | L14: =($K$6 * L11) + ($K$6 * $N$6 * L11) -> 0.0061294737 | ... N14: =($K$6 * N11) + ($K$6 * $N$6 * N11) -> 0.0036269075
C15: F E E T O T A L | E15: =SUM(E12:E14) -> 0.12692308 | F15: =SUM(F12:F14) -> 0.097633136 | G15: =SUM(G12:G14) -> 0.075102412 | H15: =SUM(H12:H14) -> 0.057771086 | I15: =SUM(I12:I14) -> 0.044439297 | J15: =SUM(J12:J14) -> 0.034184075 | K15: =SUM(K12:K14) -> 0.026295442 | L15: =SUM(L12:L14) -> 0.020227263 | ... N15: =SUM(N12:N14) -> 0.011968795
B16: B I T C O I N L E A S I N G Y I E L D A N N U A L I Z E D B T C | C16: G R O W T H | E16: =E10 * (1 + $N$6) -> 0.23076923 | F16: =(F10 - E10) * (1 + $N$6) -> 0.17751479 | G16: =(G10 - F10) * (1 + $N$6) -> 0.13654984 | H16: =(H10 - G10) * (1 + $N$6) -> 0.10503834 | I16: =(I10 - H10) * (1 + $N$6) -> 0.080798722 | J16: =(J10 - I10) * (1 + $N$6) -> 0.062152863 | K16: =(K10 - J10) * (1 + $N$6) -> 0.047809895 | L16: =(L10 - K10) * (1 + $N$6) -> 0.036776842 | M16: =(M10 - L10) * (1 + $N$6) -> 0.028289879 | N16: =(N10 - M10) * (1 + $N$6) -> 0.021761445
C17: L I Q U I D I T Y | E17: =((1 + $N$6) * $H$3) + ($H$3 * E11) -> 0.017692308 | F17: =((1 + $N$6) * $H$3) + ($H$3 * F11) -> 0.01591716 | G17: =((1 + $N$6) * $H$3) + ($H$3 * G11) -> 0.014551661 | H17: =((1 + $N$6) * $H$3) + ($H$3 * H11) -> 0.013501278 | I17: =((1 + $N$6) * $H$3) + ($H$3 * I11) -> 0.012693291 | J17: =((1 + $N$6) * $H$3) + ($H$3 * J11) -> 0.012071762 | K17: =((1 + $N$6) * $H$3) + ($H$3 * K11) -> 0.011593663 | L17: =((1 + $N$6) * $H$3) + ($H$3 * L11) -> 0.011225895 | ... N17: =((1 + $N$6) * $H$3) + ($H$3 * N11) -> 0.010725382
C18: T R A N S A C T I O N | E18: =((1 + $N$6) * $K$3) + ($K$3 * E11) -> 0.0088461538 | F18: =((1 + $N$6) * $K$3) + ($K$3 * F11) -> 0.0079585799 | G18: =((1 + $N$6) * $K$3) + ($K$3 * G11) -> 0.0072758307 | H18: =((1 + $N$6) * $K$3) + ($K$3 * H11) -> 0.006750639 | I18: =((1 + $N$6) * $K$3) + ($K$3 * I11) -> 0.0063466454 | J18: =((1 + $N$6) * $K$3) + ($K$3 * J11) -> 0.0060358811 | K18: =((1 + $N$6) * $K$3) + ($K$3 * K11) -> 0.0057968316 | L18: =((1 + $N$6) * $K$3) + ($K$3 * L11) -> 0.0056129474 | ... N18: =((1 + $N$6) * $K$3) + ($K$3 * N11) -> 0.0053626908
C19: G R O S S T O T A L | E19: =SUM(E16:E18) -> 0.25730769 | F19: =SUM(F16:F18) -> 0.20139053 | G19: =SUM(G16:G18) -> 0.15837733 | H19: =SUM(H16:H18) -> 0.12529026 | I19: =SUM(I16:I18) -> 0.099838658 | J19: =SUM(J16:J18) -> 0.080260506 | K19: =SUM(K16:K18) -> 0.06520039 | L19: =SUM(L16:L18) -> 0.053615684 | ... N19: =SUM(N16:N18) -> 0.037849517
C20: N E T T O T A L | E20: =E19 - E15 -> 0.13038462 | F20: =F19 - F15 -> 0.1037574 | G20: =G19 - G15 -> 0.08327492 | H20: =H19 - H15 -> 0.067519169 | I20: =I19 - I15 -> 0.055399361 | J20: =J19 - J15 -> 0.046076432 | K20: =K19 - K15 -> 0.038904947 | L20: =L19 - L15 -> 0.033388421 | ... N20: =N19 - N15 -> 0.025880723
B21: B I T C O I N T V L R E V E N U E A N N U A L I Z E D B T C | C21: 20000 | E21: =E14 * ($C21 / (2 + $N$6)) -> 384.61538 | F21: =F14 * ($C21 / (2 + $N$6)) -> 295.85799 | G21: =G14 * ($C21 / (2 + $N$6)) -> 227.58307 | H21: =H14 * ($C21 / (2 + $N$6)) -> 175.0639 | I21: =I14 * ($C21 / (2 + $N$6)) -> 134.66454 | J21: =J14 * ($C21 / (2 + $N$6)) -> 103.58811 | K21: =K14 * ($C21 / (2 + $N$6)) -> 79.683158 | L21: =L14 * ($C21 / (2 + $N$6)) -> 61.294737 | ... N21: =N14 * ($C21 / (2 + $N$6)) -> 36.269075
C22: 400000 | E22: =E14 * ($C22 / (2 + $N$6)) -> 7692.3077 | F22: =F14 * ($C22 / (2 + $N$6)) -> 5917.1598 | G22: =G14 * ($C22 / (2 + $N$6)) -> 4551.6614 | H22: =H14 * ($C22 / (2 + $N$6)) -> 3501.278 | I22: =I14 * ($C22 / (2 + $N$6)) -> 2693.2907 | J22: =J14 * ($C22 / (2 + $N$6)) -> 2071.7621 | K22: =K14 * ($C22 / (2 + $N$6)) -> 1593.6632 | L22: =L14 * ($C22 / (2 + $N$6)) -> 1225.8947 | ... N22: =N14 * ($C22 / (2 + $N$6)) -> 725.3815
C23: 1000000 | E23: =E14 * ($C23 / (2 + $N$6)) -> 19230.769 | F23: =F14 * ($C23 / (2 + $N$6)) -> 14792.899 | G23: =G14 * ($C23 / (2 + $N$6)) -> 11379.153 | H23: =H14 * ($C23 / (2 + $N$6)) -> 8753.1949 | I23: =I14 * ($C23 / (2 + $N$6)) -> 6733.2269 | J23: =J14 * ($C23 / (2 + $N$6)) -> 5179.4053 | K23: =K14 * ($C23 / (2 + $N$6)) -> 3984.1579 | L23: =L14 * ($C23 / (2 + $N$6)) -> 3064.7368 | ... N23: =N14 * ($C23 / (2 + $N$6)) -> 1813.4538
C24: 2100000 | E24: =E14 * ($C24 / (2 + $N$6)) -> 40384.615 | F24: =F14 * ($C24 / (2 + $N$6)) -> 31065.089 | G24: =G14 * ($C24 / (2 + $N$6)) -> 23896.222 | H24: =H14 * ($C24 / (2 + $N$6)) -> 18381.709 | I24: =I14 * ($C24 / (2 + $N$6)) -> 14139.776 | J24: =J14 * ($C24 / (2 + $N$6)) -> 10876.751 | K24: =K14 * ($C24 / (2 + $N$6)) -> 8366.7316 | L24: =L14 * ($C24 / (2 + $N$6)) -> 6435.9474 | ... N24: =N14 * ($C24 / (2 + $N$6)) -> 3808.2529
C26: T E S T C A S E | E26: B I T C O I N I N F I A T | H26: C A P I T A L I N B T C | K26: T V L I N B T C | L26: =H27*(2+N6) -> 20000
E27: 100000 | H27: 10000
E29: Y E A R 1 | F29: Y E A R 2 | G29: Y E A R 3 | H29: Y E A R 4 | I29: Y E A R 5 | J29: Y E A R 6 | K29: Y E A R 7 | L29: Y E A R 8 | M29: Y E A R 9 | N29: Y E A R 10
B30: B I T C O I N G R O W T H | C30: C U M U L A T I V E F I A T | E30: =E27 + (E27 * E9) -> 130000 | F30: =$E$3 + (E30 * $E$3) + E30 -> 169000.3 | G30: =$E$3 + (F30 * $E$3) + F30 -> 219700.69 | H30: =$E$3 + (G30 * $E$3) + G30 -> 285611.2 | I30: =$E$3 + (H30 * $E$3) + H30 -> 371294.86 | J30: =$E$3 + (I30 * $E$3) + I30 -> 482683.61 | K30: =$E$3 + (J30 * $E$3) + J30 -> 627489 | L30: =$E$3 + (K30 * $E$3) + K30 -> 815736 | M30: =$E$3 + (L30 * $E$3) + L30 -> 1060457.1 | N30: =$E$3 + (M30 * $E$3) + M30 -> 1378594.5
B31: B I T CO I N E X T R A C T I O N | C31: C U M U L A T I V E B T C | E31: =$H$27 * E10 -> 2307.6923 | F31: =$H$27 * F10 -> 4082.8402 | G31: =$H$27 * G10 -> 5448.3386 | H31: =$H$27 * H10 -> 6498.722 | I31: =$H$27 * I10 -> 7306.7093 | J31: =$H$27 * J10 -> 7928.2379 | K31: =$H$27 * K10 -> 8406.3368 | L31: =$H$27 * L10 -> 8774.1053 | ... N31: =$H$27 * N10 -> 9274.6185
C32: R E M A I N I N G B T C | E32: =$H$27 * E11 -> 7692.3077 | F32: =$H$27 * F11 -> 5917.1598 | G32: =$H$27 * G11 -> 4551.6614 | H32: =$H$27 * H11 -> 3501.278 | I32: =$H$27 * I11 -> 2693.2907 | J32: =$H$27 * J11 -> 2071.7621 | K32: =$H$27 * K11 -> 1593.6632 | L32: =$H$27 * L11 -> 1225.8947 | ... N32: =$H$27 * N11 -> 725.3815
B33: B I T C O I N L E A S I N G F E E S A N N U A L I Z E D B T C | C33: S E C U R I T Y | E33: =$H$27 * E12 -> 884.61538 | F33: =$H$27 * F12 -> 680.47337 | G33: =$H$27 * G12 -> 523.44106 | H33: =$H$27 * H12 -> 402.64697 | I33: =$H$27 * I12 -> 309.72844 | J33: =$H$27 * J12 -> 238.25264 | K33: =$H$27 * K12 -> 183.27126 | L33: =$H$27 * L12 -> 140.9779 | ... N33: =$H$27 * N12 -> 83.418873
C34: D E B T | E34: =$H$27 * E13 -> 0 | F34: =$H$27 * F13 -> 0 | G34: =$H$27 * G13 -> 0 | H34: =$H$27 * H13 -> 0 | I34: =$H$27 * I13 -> 0 | J34: =$H$27 * J13 -> 0 | K34: =$H$27 * K13 -> 0 | L34: =$H$27 * L13 -> 0 | ... N34: =$H$27 * N13 -> 0
C35: S E R V I C E | E35: =$H$27 * E14 -> 384.61538 | F35: =$H$27 * F14 -> 295.85799 | G35: =$H$27 * G14 -> 227.58307 | H35: =$H$27 * H14 -> 175.0639 | I35: =$H$27 * I14 -> 134.66454 | J35: =$H$27 * J14 -> 103.58811 | K35: =$H$27 * K14 -> 79.683158 | L35: =$H$27 * L14 -> 61.294737 | ... N35: =$H$27 * N14 -> 36.269075
C36: F E E T O T A L | E36: =$H$27 * E15 -> 1269.2308 | F36: =$H$27 * F15 -> 976.33136 | G36: =$H$27 * G15 -> 751.02412 | H36: =$H$27 * H15 -> 577.71086 | I36: =$H$27 * I15 -> 444.39297 | J36: =$H$27 * J15 -> 341.84075 | K36: =$H$27 * K15 -> 262.95442 | L36: =$H$27 * L15 -> 202.27263 | ... N36: =$H$27 * N15 -> 119.68795
B37: B I T C O I N L E A S I N G Y I E L D A N N U A L I Z E D B T C | C37: G R O W T H | E37: =$H$27 * E16 -> 2307.6923 | F37: =$H$27 * F16 -> 1775.1479 | G37: =$H$27 * G16 -> 1365.4984 | H37: =$H$27 * H16 -> 1050.3834 | I37: =$H$27 * I16 -> 807.98722 | J37: =$H$27 * J16 -> 621.52863 | K37: =$H$27 * K16 -> 478.09895 | L37: =$H$27 * L16 -> 367.76842 | ... N37: =$H$27 * N16 -> 217.61445
C38: L I Q U I D I T Y | E38: =$H$27 * E17 -> 176.92308 | F38: =$H$27 * F17 -> 159.1716 | G38: =$H$27 * G17 -> 145.51661 | H38: =$H$27 * H17 -> 135.01278 | I38: =$H$27 * I17 -> 126.93291 | J38: =$H$27 * J17 -> 120.71762 | K38: =$H$27 * K17 -> 115.93663 | L38: =$H$27 * L17 -> 112.25895 | ... N38: =$H$27 * N17 -> 107.25382
C39: T R A N S A C T I O N | E39: =$H$27 * E18 -> 88.461538 | F39: =$H$27 * F18 -> 79.585799 | G39: =$H$27 * G18 -> 72.758307 | H39: =$H$27 * H18 -> 67.50639 | I39: =$H$27 * I18 -> 63.466454 | J39: =$H$27 * J18 -> 60.358811 | K39: =$H$27 * K18 -> 57.968316 | L39: =$H$27 * L18 -> 56.129474 | ... N39: =$H$27 * N18 -> 53.626908
C40: G R O S S T O T A L | E40: =$H$27 * E19 -> 2573.0769 | F40: =$H$27 * F19 -> 2013.9053 | G40: =$H$27 * G19 -> 1583.7733 | H40: =$H$27 * H19 -> 1252.9026 | I40: =$H$27 * I19 -> 998.38658 | J40: =$H$27 * J19 -> 802.60506 | K40: =$H$27 * K19 -> 652.0039 | L40: =$H$27 * L19 -> 536.15684 | ... N40: =$H$27 * N19 -> 378.49517
C41: N E T T O T A L | E41: =$H$27 * E20 -> 1303.8462 | F41: =$H$27 * F20 -> 1037.574 | G41: =$H$27 * G20 -> 832.7492 | H41: =$H$27 * H20 -> 675.19169 | I41: =$H$27 * I20 -> 553.99361 | J41: =$H$27 * J20 -> 460.76432 | K41: =$H$27 * K20 -> 389.04947 | L41: =$H$27 * L20 -> 333.88421 | ... N41: =$H$27 * N20 -> 258.80723

Sheet 2.5X
B2: A M P L I F Y Y O U R B I T C O I N O N T H E L I G H T N I N G N E T W O R K | C2: B I T C O I N L E A S I N G Y I E L D A N N U A L I Z E D F I A T O R B T C | E2: G R O W T H | H2: L I Q U I D I T Y | K2: T R A N S A C T I O N | N2: D E B T L E A S E T O C A P I T A L
E3: =SHARED_VARIABLES!H5 -> 0.3 | H3: =SHARED_VARIABLES!L5 -> 0.01 | K3: =SHARED_VARIABLES!P5 -> 0.005
C5: B I T C O I N L E A S I N G F E E S A N N U A L I Z E D F I A T | E5: S E C U R I T Y | H5: D E B T | K5: S E R V I C E
E6: =SHARED_VARIABLES!H8 -> 0.115 | H6: =SHARED_VARIABLES!L8 -> 0.075 | K6: =SHARED_VARIABLES!P8 -> 0.05 | N6: =SHARED_VARIABLES!H12 -> 0.5
E8: Y E A R 1 | F8: Y E A R 2 | G8: Y E A R 3 | H8: Y E A R 4 | I8: Y E A R 5 | J8: Y E A R 6 | K8: Y E A R 7 | L8: Y E A R 8 | M8: Y E A R 9 | N8: Y E A R 10
B9: B I T C O I N G R O W T H | C9: C U M U L A T I V E F I A T | E9: =$E$3 -> 0.3 | F9: =$E$3 + (E9 * $E$3) + E9 -> 0.69 | G9: =$E$3 + (F9 * $E$3) + F9 -> 1.197 | H9: =$E$3 + (G9 * $E$3) + G9 -> 1.8561 | I9: =$E$3 + (H9 * $E$3) + H9 -> 2.71293 | J9: =$E$3 + (I9 * $E$3) + I9 -> 3.826809 | K9: =$E$3 + (J9 * $E$3) + J9 -> 5.2748517 | L9: =$E$3 + (K9 * $E$3) + K9 -> 7.1573072 | M9: =$E$3 + (L9 * $E$3) + L9 -> 9.6044994 | N9: =$E$3 + (M9 * $E$3) + M9 -> 12.785849
B10: B I T CO I N E X T R A C T I O N | C10: C U M U L A T I V E B T C | E10: =((1 + E9) - 1) / (1 + E9) -> 0.23076923 | F10: =((1 + F9) - 1) / (1 + F9) -> 0.40828402 | G10: =((1 + G9) - 1) / (1 + G9) -> 0.54483386 | H10: =((1 + H9) - 1) / (1 + H9) -> 0.6498722 | I10: =((1 + I9) - 1) / (1 + I9) -> 0.73067093 | J10: =((1 + J9) - 1) / (1 + J9) -> 0.79282379 | K10: =((1 + K9) - 1) / (1 + K9) -> 0.84063368 | L10: =((1 + L9) - 1) / (1 + L9) -> 0.87741053 | ... N10: =((1 + N9) - 1) / (1 + N9) -> 0.92746185
C11: R E M A I N I N G B T C | E11: =1 - E10 -> 0.76923077 | F11: =1 - F10 -> 0.59171598 | G11: =1 - G10 -> 0.45516614 | H11: =1 - H10 -> 0.3501278 | I11: =1 - I10 -> 0.26932907 | J11: =1 - J10 -> 0.20717621 | K11: =1 - K10 -> 0.15936632 | L11: =1 - L10 -> 0.12258947 | ... N11: =1 - N10 -> 0.07253815
B12: B I T C O I N L E A S I N G F E E S A N N U A L I Z E D B T C | C12: S E C U R I T Y | E12: =$E$6 * E11 -> 0.088461538 | F12: =$E$6 * F11 -> 0.068047337 | G12: =$E$6 * G11 -> 0.052344106 | H12: =$E$6 * H11 -> 0.040264697 | I12: =$E$6 * I11 -> 0.030972844 | J12: =$E$6 * J11 -> 0.023825264 | K12: =$E$6 * K11 -> 0.018327126 | L12: =$E$6 * L11 -> 0.01409779 | ... N12: =$E$6 * N11 -> 0.0083418873
C13: D E B T | E13: =$H$6 * $N$6 * E11 -> 0.028846154 | F13: =$H$6 * $N$6 * F11 -> 0.022189349 | G13: =$H$6 * $N$6 * G11 -> 0.01706873 | H13: =$H$6 * $N$6 * H11 -> 0.013129792 | I13: =$H$6 * $N$6 * I11 -> 0.01009984 | J13: =$H$6 * $N$6 * J11 -> 0.0077691079 | K13: =$H$6 * $N$6 * K11 -> 0.0059762369 | L13: =$H$6 * $N$6 * L11 -> 0.0045971053 | ... N13: =$H$6 * $N$6 * N11 -> 0.0027201806
C14: S E R V I C E | E14: =($K$6 * E11) + ($K$6 * $N$6 * E11) -> 0.057692308 | F14: =($K$6 * F11) + ($K$6 * $N$6 * F11) -> 0.044378698 | G14: =($K$6 * G11) + ($K$6 * $N$6 * G11) -> 0.03413746 | H14: =($K$6 * H11) + ($K$6 * $N$6 * H11) -> 0.026259585 | I14: =($K$6 * I11) + ($K$6 * $N$6 * I11) -> 0.020199681 | J14: =($K$6 * J11) + ($K$6 * $N$6 * J11) -> 0.015538216 | K14: =($K$6 * K11) + ($K$6 * $N$6 * K11) -> 0.011952474 | L14: =($K$6 * L11) + ($K$6 * $N$6 * L11) -> 0.0091942105 | ... N14: =($K$6 * N11) + ($K$6 * $N$6 * N11) -> 0.0054403613
C15: F E E T O T A L | E15: =SUM(E12:E14) -> 0.175 | F15: =SUM(F12:F14) -> 0.13461538 | G15: =SUM(G12:G14) -> 0.1035503 | H15: =SUM(H12:H14) -> 0.079654074 | I15: =SUM(I12:I14) -> 0.061272364 | J15: =SUM(J12:J14) -> 0.047132588 | K15: =SUM(K12:K14) -> 0.036255837 | L15: =SUM(L12:L14) -> 0.027889105 | ... N15: =SUM(N12:N14) -> 0.016502429
B16: B I T C O I N L E A S I N G Y I E L D A N N U A L I Z E D B T C | C16: G R O W T H | E16: =E10 * (1 + $N$6) -> 0.34615385 | F16: =(F10 - E10) * (1 + $N$6) -> 0.26627219 | G16: =(G10 - F10) * (1 + $N$6) -> 0.20482476 | H16: =(H10 - G10) * (1 + $N$6) -> 0.15755751 | I16: =(I10 - H10) * (1 + $N$6) -> 0.12119808 | J16: =(J10 - I10) * (1 + $N$6) -> 0.093229295 | K16: =(K10 - J10) * (1 + $N$6) -> 0.071714842 | L16: =(L10 - K10) * (1 + $N$6) -> 0.055165263 | M16: =(M10 - L10) * (1 + $N$6) -> 0.042434818 | N16: =(N10 - M10) * (1 + $N$6) -> 0.032642168
C17: L I Q U I D I T Y | E17: =((1 + $N$6) * $H$3) + ($H$3 * E11) -> 0.022692308 | F17: =((1 + $N$6) * $H$3) + ($H$3 * F11) -> 0.02091716 | G17: =((1 + $N$6) * $H$3) + ($H$3 * G11) -> 0.019551661 | H17: =((1 + $N$6) * $H$3) + ($H$3 * H11) -> 0.018501278 | I17: =((1 + $N$6) * $H$3) + ($H$3 * I11) -> 0.017693291 | J17: =((1 + $N$6) * $H$3) + ($H$3 * J11) -> 0.017071762 | K17: =((1 + $N$6) * $H$3) + ($H$3 * K11) -> 0.016593663 | L17: =((1 + $N$6) * $H$3) + ($H$3 * L11) -> 0.016225895 | ... N17: =((1 + $N$6) * $H$3) + ($H$3 * N11) -> 0.015725382
C18: T R A N S A C T I O N | E18: =((1 + $N$6) * $K$3) + ($K$3 * E11) -> 0.011346154 | F18: =((1 + $N$6) * $K$3) + ($K$3 * F11) -> 0.01045858 | G18: =((1 + $N$6) * $K$3) + ($K$3 * G11) -> 0.0097758307 | H18: =((1 + $N$6) * $K$3) + ($K$3 * H11) -> 0.009250639 | I18: =((1 + $N$6) * $K$3) + ($K$3 * I11) -> 0.0088466454 | J18: =((1 + $N$6) * $K$3) + ($K$3 * J11) -> 0.0085358811 | K18: =((1 + $N$6) * $K$3) + ($K$3 * K11) -> 0.0082968316 | L18: =((1 + $N$6) * $K$3) + ($K$3 * L11) -> 0.0081129474 | ... N18: =((1 + $N$6) * $K$3) + ($K$3 * N11) -> 0.0078626908
C19: G R O S S T O T A L | E19: =SUM(E16:E18) -> 0.38019231 | F19: =SUM(F16:F18) -> 0.29764793 | G19: =SUM(G16:G18) -> 0.23415225 | H19: =SUM(H16:H18) -> 0.18530943 | I19: =SUM(I16:I18) -> 0.14773802 | J19: =SUM(J16:J18) -> 0.11883694 | K19: =SUM(K16:K18) -> 0.096605337 | L19: =SUM(L16:L18) -> 0.079504105 | ... N19: =SUM(N16:N18) -> 0.05623024
C20: N E T T O T A L | E20: =E19 - E15 -> 0.20519231 | F20: =F19 - F15 -> 0.16303254 | G20: =G19 - G15 -> 0.13060196 | H20: =H19 - H15 -> 0.10565535 | I20: =I19 - I15 -> 0.086465655 | J20: =J19 - J15 -> 0.07170435 | K20: =K19 - K15 -> 0.0603495 | L20: =L19 - L15 -> 0.051615 | ... N20: =N19 - N15 -> 0.039727811
B21: B I T C O I N T V L R E V E N U E A N N U A L I Z E D B T C | C21: 20000 | E21: =E14 * ($C21 / (2 + $N$6)) -> 461.53846 | F21: =F14 * ($C21 / (2 + $N$6)) -> 355.02959 | G21: =G14 * ($C21 / (2 + $N$6)) -> 273.09968 | H21: =H14 * ($C21 / (2 + $N$6)) -> 210.07668 | I21: =I14 * ($C21 / (2 + $N$6)) -> 161.59744 | J21: =J14 * ($C21 / (2 + $N$6)) -> 124.30573 | K21: =K14 * ($C21 / (2 + $N$6)) -> 95.61979 | L21: =L14 * ($C21 / (2 + $N$6)) -> 73.553684 | ... N21: =N14 * ($C21 / (2 + $N$6)) -> 43.52289
C22: 400000 | E22: =E14 * ($C22 / (2 + $N$6)) -> 9230.7692 | F22: =F14 * ($C22 / (2 + $N$6)) -> 7100.5917 | G22: =G14 * ($C22 / (2 + $N$6)) -> 5461.9936 | H22: =H14 * ($C22 / (2 + $N$6)) -> 4201.5336 | I22: =I14 * ($C22 / (2 + $N$6)) -> 3231.9489 | J22: =J14 * ($C22 / (2 + $N$6)) -> 2486.1145 | K22: =K14 * ($C22 / (2 + $N$6)) -> 1912.3958 | L22: =L14 * ($C22 / (2 + $N$6)) -> 1471.0737 | ... N22: =N14 * ($C22 / (2 + $N$6)) -> 870.4578
C23: 1000000 | E23: =E14 * ($C23 / (2 + $N$6)) -> 23076.923 | F23: =F14 * ($C23 / (2 + $N$6)) -> 17751.479 | G23: =G14 * ($C23 / (2 + $N$6)) -> 13654.984 | H23: =H14 * ($C23 / (2 + $N$6)) -> 10503.834 | I23: =I14 * ($C23 / (2 + $N$6)) -> 8079.8722 | J23: =J14 * ($C23 / (2 + $N$6)) -> 6215.2863 | K23: =K14 * ($C23 / (2 + $N$6)) -> 4780.9895 | L23: =L14 * ($C23 / (2 + $N$6)) -> 3677.6842 | ... N23: =N14 * ($C23 / (2 + $N$6)) -> 2176.1445
C24: 2100000 | E24: =E14 * ($C24 / (2 + $N$6)) -> 48461.538 | F24: =F14 * ($C24 / (2 + $N$6)) -> 37278.107 | G24: =G14 * ($C24 / (2 + $N$6)) -> 28675.467 | H24: =H14 * ($C24 / (2 + $N$6)) -> 22058.051 | I24: =I14 * ($C24 / (2 + $N$6)) -> 16967.732 | J24: =J14 * ($C24 / (2 + $N$6)) -> 13052.101 | K24: =K14 * ($C24 / (2 + $N$6)) -> 10040.078 | L24: =L14 * ($C24 / (2 + $N$6)) -> 7723.1369 | ... N24: =N14 * ($C24 / (2 + $N$6)) -> 4569.9035
C26: T E S T C A S E | E26: B I T C O I N I N F I A T | H26: C A P I T A L I N B T C | K26: T V L I N B T C | L26: =H27*(2+N6) -> 20000
E27: 100000 | H27: 8000
E29: Y E A R 1 | F29: Y E A R 2 | G29: Y E A R 3 | H29: Y E A R 4 | I29: Y E A R 5 | J29: Y E A R 6 | K29: Y E A R 7 | L29: Y E A R 8 | M29: Y E A R 9 | N29: Y E A R 10
B30: B I T C O I N G R O W T H | C30: C U M U L A T I V E F I A T | E30: =E27 + (E27 * E9) -> 130000 | F30: =$E$3 + (E30 * $E$3) + E30 -> 169000.3 | G30: =$E$3 + (F30 * $E$3) + F30 -> 219700.69 | H30: =$E$3 + (G30 * $E$3) + G30 -> 285611.2 | I30: =$E$3 + (H30 * $E$3) + H30 -> 371294.86 | J30: =$E$3 + (I30 * $E$3) + I30 -> 482683.61 | K30: =$E$3 + (J30 * $E$3) + J30 -> 627489 | L30: =$E$3 + (K30 * $E$3) + K30 -> 815736 | M30: =$E$3 + (L30 * $E$3) + L30 -> 1060457.1 | N30: =$E$3 + (M30 * $E$3) + M30 -> 1378594.5
B31: B I T CO I N E X T R A C T I O N | C31: C U M U L A T I V E B T C | E31: =$H$27 * E10 -> 1846.1538 | F31: =$H$27 * F10 -> 3266.2722 | G31: =$H$27 * G10 -> 4358.6709 | H31: =$H$27 * H10 -> 5198.9776 | I31: =$H$27 * I10 -> 5845.3674 | J31: =$H$27 * J10 -> 6342.5903 | K31: =$H$27 * K10 -> 6725.0695 | L31: =$H$27 * L10 -> 7019.2842 | ... N31: =$H$27 * N10 -> 7419.6948
C32: R E M A I N I N G B T C | E32: =$H$27 * E11 -> 6153.8462 | F32: =$H$27 * F11 -> 4733.7278 | G32: =$H$27 * G11 -> 3641.3291 | H32: =$H$27 * H11 -> 2801.0224 | I32: =$H$27 * I11 -> 2154.6326 | J32: =$H$27 * J11 -> 1657.4097 | K32: =$H$27 * K11 -> 1274.9305 | L32: =$H$27 * L11 -> 980.71579 | ... N32: =$H$27 * N11 -> 580.3052
B33: B I T C O I N L E A S I N G F E E S A N N U A L I Z E D B T C | C33: S E C U R I T Y | E33: =$H$27 * E12 -> 707.69231 | F33: =$H$27 * F12 -> 544.3787 | G33: =$H$27 * G12 -> 418.75284 | H33: =$H$27 * H12 -> 322.11757 | I33: =$H$27 * I12 -> 247.78275 | J33: =$H$27 * J12 -> 190.60211 | K33: =$H$27 * K12 -> 146.61701 | L33: =$H$27 * L12 -> 112.78232 | ... N33: =$H$27 * N12 -> 66.735098
C34: D E B T | E34: =$H$27 * E13 -> 230.76923 | F34: =$H$27 * F13 -> 177.51479 | G34: =$H$27 * G13 -> 136.54984 | H34: =$H$27 * H13 -> 105.03834 | I34: =$H$27 * I13 -> 80.798722 | J34: =$H$27 * J13 -> 62.152863 | K34: =$H$27 * K13 -> 47.809895 | L34: =$H$27 * L13 -> 36.776842 | ... N34: =$H$27 * N13 -> 21.761445
C35: S E R V I C E | E35: =$H$27 * E14 -> 461.53846 | F35: =$H$27 * F14 -> 355.02959 | G35: =$H$27 * G14 -> 273.09968 | H35: =$H$27 * H14 -> 210.07668 | I35: =$H$27 * I14 -> 161.59744 | J35: =$H$27 * J14 -> 124.30573 | K35: =$H$27 * K14 -> 95.61979 | L35: =$H$27 * L14 -> 73.553684 | ... N35: =$H$27 * N14 -> 43.52289
C36: F E E T O T A L | E36: =$H$27 * E15 -> 1400 | F36: =$H$27 * F15 -> 1076.9231 | G36: =$H$27 * G15 -> 828.40237 | H36: =$H$27 * H15 -> 637.23259 | I36: =$H$27 * I15 -> 490.17892 | J36: =$H$27 * J15 -> 377.0607 | K36: =$H$27 * K15 -> 290.0467 | L36: =$H$27 * L15 -> 223.11284 | ... N36: =$H$27 * N15 -> 132.01943
B37: B I T C O I N L E A S I N G Y I E L D A N N U A L I Z E D B T C | C37: G R O W T H | E37: =$H$27 * E16 -> 2769.2308 | F37: =$H$27 * F16 -> 2130.1775 | G37: =$H$27 * G16 -> 1638.5981 | H37: =$H$27 * H16 -> 1260.4601 | I37: =$H$27 * I16 -> 969.58467 | J37: =$H$27 * J16 -> 745.83436 | K37: =$H$27 * K16 -> 573.71874 | L37: =$H$27 * L16 -> 441.32211 | ... N37: =$H$27 * N16 -> 261.13734
C38: L I Q U I D I T Y | E38: =$H$27 * E17 -> 181.53846 | F38: =$H$27 * F17 -> 167.33728 | G38: =$H$27 * G17 -> 156.41329 | H38: =$H$27 * H17 -> 148.01022 | I38: =$H$27 * I17 -> 141.54633 | J38: =$H$27 * J17 -> 136.5741 | K38: =$H$27 * K17 -> 132.74931 | L38: =$H$27 * L17 -> 129.80716 | ... N38: =$H$27 * N17 -> 125.80305
C39: T R A N S A C T I O N | E39: =$H$27 * E18 -> 90.769231 | F39: =$H$27 * F18 -> 83.668639 | G39: =$H$27 * G18 -> 78.206645 | H39: =$H$27 * H18 -> 74.005112 | I39: =$H$27 * I18 -> 70.773163 | J39: =$H$27 * J18 -> 68.287048 | K39: =$H$27 * K18 -> 66.374653 | L39: =$H$27 * L18 -> 64.903579 | ... N39: =$H$27 * N18 -> 62.901526
C40: G R O S S T O T A L | E40: =$H$27 * E19 -> 3041.5385 | F40: =$H$27 * F19 -> 2381.1834 | G40: =$H$27 * G19 -> 1873.218 | H40: =$H$27 * H19 -> 1482.4754 | I40: =$H$27 * I19 -> 1181.9042 | J40: =$H$27 * J19 -> 950.69551 | K40: =$H$27 * K19 -> 772.8427 | L40: =$H$27 * L19 -> 636.03284 | ... N40: =$H$27 * N19 -> 449.84192
C41: N E T T O T A L | E41: =$H$27 * E20 -> 1641.5385 | F41: =$H$27 * F20 -> 1304.2604 | G41: =$H$27 * G20 -> 1044.8157 | H41: =$H$27 * H20 -> 845.24281 | I41: =$H$27 * I20 -> 691.72524 | J41: =$H$27 * J20 -> 573.6348 | K41: =$H$27 * K20 -> 482.796 | L41: =$H$27 * L20 -> 412.92 | ... N41: =$H$27 * N20 -> 317.82249

Sheet 3X
B2: A M P L I F Y Y O U R B I T C O I N O N T H E L I G H T N I N G N E T W O R K | C2: B I T C O I N L E A S I N G Y I E L D A N N U A L I Z E D F I A T O R B T C | E2: G R O W T H | H2: L I Q U I D I T Y | K2: T R A N S A C T I O N | N2: D E B T L E A S E T O C A P I T A L
E3: =SHARED_VARIABLES!H5 -> 0.3 | H3: =SHARED_VARIABLES!L5 -> 0.01 | K3: =SHARED_VARIABLES!P5 -> 0.005
C5: B I T C O I N L E A S I N G F E E S A N N U A L I Z E D F I A T | E5: S E C U R I T Y | H5: D E B T | K5: S E R V I C E
E6: =SHARED_VARIABLES!H8 -> 0.115 | H6: =SHARED_VARIABLES!L8 -> 0.075 | K6: =SHARED_VARIABLES!P8 -> 0.05 | N6: =SHARED_VARIABLES!J12 -> 1
E8: Y E A R 1 | F8: Y E A R 2 | G8: Y E A R 3 | H8: Y E A R 4 | I8: Y E A R 5 | J8: Y E A R 6 | K8: Y E A R 7 | L8: Y E A R 8 | M8: Y E A R 9 | N8: Y E A R 10
B9: B I T C O I N G R O W T H | C9: C U M U L A T I V E F I A T | E9: =$E$3 -> 0.3 | F9: =$E$3 + (E9 * $E$3) + E9 -> 0.69 | G9: =$E$3 + (F9 * $E$3) + F9 -> 1.197 | H9: =$E$3 + (G9 * $E$3) + G9 -> 1.8561 | I9: =$E$3 + (H9 * $E$3) + H9 -> 2.71293 | J9: =$E$3 + (I9 * $E$3) + I9 -> 3.826809 | K9: =$E$3 + (J9 * $E$3) + J9 -> 5.2748517 | L9: =$E$3 + (K9 * $E$3) + K9 -> 7.1573072 | M9: =$E$3 + (L9 * $E$3) + L9 -> 9.6044994 | N9: =$E$3 + (M9 * $E$3) + M9 -> 12.785849
B10: B I T CO I N E X T R A C T I O N | C10: C U M U L A T I V E B T C | E10: =((1 + E9) - 1) / (1 + E9) -> 0.23076923 | F10: =((1 + F9) - 1) / (1 + F9) -> 0.40828402 | G10: =((1 + G9) - 1) / (1 + G9) -> 0.54483386 | H10: =((1 + H9) - 1) / (1 + H9) -> 0.6498722 | I10: =((1 + I9) - 1) / (1 + I9) -> 0.73067093 | J10: =((1 + J9) - 1) / (1 + J9) -> 0.79282379 | K10: =((1 + K9) - 1) / (1 + K9) -> 0.84063368 | L10: =((1 + L9) - 1) / (1 + L9) -> 0.87741053 | ... N10: =((1 + N9) - 1) / (1 + N9) -> 0.92746185
C11: R E M A I N I N G B T C | E11: =1 - E10 -> 0.76923077 | F11: =1 - F10 -> 0.59171598 | G11: =1 - G10 -> 0.45516614 | H11: =1 - H10 -> 0.3501278 | I11: =1 - I10 -> 0.26932907 | J11: =1 - J10 -> 0.20717621 | K11: =1 - K10 -> 0.15936632 | L11: =1 - L10 -> 0.12258947 | ... N11: =1 - N10 -> 0.07253815
B12: B I T C O I N L E A S I N G F E E S A N N U A L I Z E D B T C | C12: S E C U R I T Y | E12: =$E$6 * E11 -> 0.088461538 | F12: =$E$6 * F11 -> 0.068047337 | G12: =$E$6 * G11 -> 0.052344106 | H12: =$E$6 * H11 -> 0.040264697 | I12: =$E$6 * I11 -> 0.030972844 | J12: =$E$6 * J11 -> 0.023825264 | K12: =$E$6 * K11 -> 0.018327126 | L12: =$E$6 * L11 -> 0.01409779 | ... N12: =$E$6 * N11 -> 0.0083418873
C13: D E B T | E13: =$H$6 * $N$6 * E11 -> 0.057692308 | F13: =$H$6 * $N$6 * F11 -> 0.044378698 | G13: =$H$6 * $N$6 * G11 -> 0.03413746 | H13: =$H$6 * $N$6 * H11 -> 0.026259585 | I13: =$H$6 * $N$6 * I11 -> 0.020199681 | J13: =$H$6 * $N$6 * J11 -> 0.015538216 | K13: =$H$6 * $N$6 * K11 -> 0.011952474 | L13: =$H$6 * $N$6 * L11 -> 0.0091942105 | ... N13: =$H$6 * $N$6 * N11 -> 0.0054403613
C14: S E R V I C E | E14: =($K$6 * E11) + ($K$6 * $N$6 * E11) -> 0.076923077 | F14: =($K$6 * F11) + ($K$6 * $N$6 * F11) -> 0.059171598 | G14: =($K$6 * G11) + ($K$6 * $N$6 * G11) -> 0.045516614 | H14: =($K$6 * H11) + ($K$6 * $N$6 * H11) -> 0.03501278 | I14: =($K$6 * I11) + ($K$6 * $N$6 * I11) -> 0.026932907 | J14: =($K$6 * J11) + ($K$6 * $N$6 * J11) -> 0.020717621 | K14: =($K$6 * K11) + ($K$6 * $N$6 * K11) -> 0.015936632 | L14: =($K$6 * L11) + ($K$6 * $N$6 * L11) -> 0.012258947 | ... N14: =($K$6 * N11) + ($K$6 * $N$6 * N11) -> 0.007253815
C15: F E E T O T A L | E15: =SUM(E12:E14) -> 0.22307692 | F15: =SUM(F12:F14) -> 0.17159763 | G15: =SUM(G12:G14) -> 0.13199818 | H15: =SUM(H12:H14) -> 0.10153706 | I15: =SUM(I12:I14) -> 0.078105432 | J15: =SUM(J12:J14) -> 0.060081101 | K15: =SUM(K12:K14) -> 0.046216232 | L15: =SUM(L12:L14) -> 0.035550947 | ... N15: =SUM(N12:N14) -> 0.021036064
B16: B I T C O I N L E A S I N G Y I E L D A N N U A L I Z E D B T C | C16: G R O W T H | E16: =E10 * (1 + $N$6) -> 0.46153846 | F16: =(F10 - E10) * (1 + $N$6) -> 0.35502959 | G16: =(G10 - F10) * (1 + $N$6) -> 0.27309968 | H16: =(H10 - G10) * (1 + $N$6) -> 0.21007668 | I16: =(I10 - H10) * (1 + $N$6) -> 0.16159744 | J16: =(J10 - I10) * (1 + $N$6) -> 0.12430573 | K16: =(K10 - J10) * (1 + $N$6) -> 0.09561979 | L16: =(L10 - K10) * (1 + $N$6) -> 0.073553684 | M16: =(M10 - L10) * (1 + $N$6) -> 0.056579757 | N16: =(N10 - M10) * (1 + $N$6) -> 0.04352289
C17: L I Q U I D I T Y | E17: =((1 + $N$6) * $H$3) + ($H$3 * E11) -> 0.027692308 | F17: =((1 + $N$6) * $H$3) + ($H$3 * F11) -> 0.02591716 | G17: =((1 + $N$6) * $H$3) + ($H$3 * G11) -> 0.024551661 | H17: =((1 + $N$6) * $H$3) + ($H$3 * H11) -> 0.023501278 | I17: =((1 + $N$6) * $H$3) + ($H$3 * I11) -> 0.022693291 | J17: =((1 + $N$6) * $H$3) + ($H$3 * J11) -> 0.022071762 | K17: =((1 + $N$6) * $H$3) + ($H$3 * K11) -> 0.021593663 | L17: =((1 + $N$6) * $H$3) + ($H$3 * L11) -> 0.021225895 | ... N17: =((1 + $N$6) * $H$3) + ($H$3 * N11) -> 0.020725382
C18: T R A N S A C T I O N | E18: =((1 + $N$6) * $K$3) + ($K$3 * E11) -> 0.013846154 | F18: =((1 + $N$6) * $K$3) + ($K$3 * F11) -> 0.01295858 | G18: =((1 + $N$6) * $K$3) + ($K$3 * G11) -> 0.012275831 | H18: =((1 + $N$6) * $K$3) + ($K$3 * H11) -> 0.011750639 | I18: =((1 + $N$6) * $K$3) + ($K$3 * I11) -> 0.011346645 | J18: =((1 + $N$6) * $K$3) + ($K$3 * J11) -> 0.011035881 | K18: =((1 + $N$6) * $K$3) + ($K$3 * K11) -> 0.010796832 | L18: =((1 + $N$6) * $K$3) + ($K$3 * L11) -> 0.010612947 | ... N18: =((1 + $N$6) * $K$3) + ($K$3 * N11) -> 0.010362691
C19: G R O S S T O T A L | E19: =SUM(E16:E18) -> 0.50307692 | F19: =SUM(F16:F18) -> 0.39390533 | G19: =SUM(G16:G18) -> 0.30992717 | H19: =SUM(H16:H18) -> 0.24532859 | I19: =SUM(I16:I18) -> 0.19563738 | J19: =SUM(J16:J18) -> 0.15741337 | K19: =SUM(K16:K18) -> 0.12801028 | L19: =SUM(L16:L18) -> 0.10539253 | ... N19: =SUM(N16:N18) -> 0.074610962
C20: N E T T O T A L | E20: =E19 - E15 -> 0.28 | F20: =F19 - F15 -> 0.22230769 | G20: =G19 - G15 -> 0.17792899 | H20: =H19 - H15 -> 0.14379153 | I20: =I19 - I15 -> 0.11753195 | J20: =J19 - J15 -> 0.097332269 | K20: =K19 - K15 -> 0.081794053 | L20: =L19 - L15 -> 0.069841579 | ... N20: =N19 - N15 -> 0.053574899
B21: B I T C O I N T V L R E V E N U E A N N U A L I Z E D B T C | C21: 20000 | E21: =E14 * ($C21 / (2 + $N$6)) -> 512.82051 | F21: =F14 * ($C21 / (2 + $N$6)) -> 394.47732 | G21: =G14 * ($C21 / (2 + $N$6)) -> 303.44409 | H21: =H14 * ($C21 / (2 + $N$6)) -> 233.41853 | I21: =I14 * ($C21 / (2 + $N$6)) -> 179.55272 | J21: =J14 * ($C21 / (2 + $N$6)) -> 138.11747 | K21: =K14 * ($C21 / (2 + $N$6)) -> 106.24421 | L21: =L14 * ($C21 / (2 + $N$6)) -> 81.726316 | ... N21: =N14 * ($C21 / (2 + $N$6)) -> 48.358767
C22: 400000 | E22: =E14 * ($C22 / (2 + $N$6)) -> 10256.41 | F22: =F14 * ($C22 / (2 + $N$6)) -> 7889.5464 | G22: =G14 * ($C22 / (2 + $N$6)) -> 6068.8818 | H22: =H14 * ($C22 / (2 + $N$6)) -> 4668.3706 | I22: =I14 * ($C22 / (2 + $N$6)) -> 3591.0543 | J22: =J14 * ($C22 / (2 + $N$6)) -> 2762.3495 | K22: =K14 * ($C22 / (2 + $N$6)) -> 2124.8842 | L22: =L14 * ($C22 / (2 + $N$6)) -> 1634.5263 | ... N22: =N14 * ($C22 / (2 + $N$6)) -> 967.17534
C23: 1000000 | E23: =E14 * ($C23 / (2 + $N$6)) -> 25641.026 | F23: =F14 * ($C23 / (2 + $N$6)) -> 19723.866 | G23: =G14 * ($C23 / (2 + $N$6)) -> 15172.205 | H23: =H14 * ($C23 / (2 + $N$6)) -> 11670.927 | I23: =I14 * ($C23 / (2 + $N$6)) -> 8977.6358 | J23: =J14 * ($C23 / (2 + $N$6)) -> 6905.8737 | K23: =K14 * ($C23 / (2 + $N$6)) -> 5312.2105 | L23: =L14 * ($C23 / (2 + $N$6)) -> 4086.3158 | ... N23: =N14 * ($C23 / (2 + $N$6)) -> 2417.9383
C24: 2100000 | E24: =E14 * ($C24 / (2 + $N$6)) -> 53846.154 | F24: =F14 * ($C24 / (2 + $N$6)) -> 41420.118 | G24: =G14 * ($C24 / (2 + $N$6)) -> 31861.629 | H24: =H14 * ($C24 / (2 + $N$6)) -> 24508.946 | I24: =I14 * ($C24 / (2 + $N$6)) -> 18853.035 | J24: =J14 * ($C24 / (2 + $N$6)) -> 14502.335 | K24: =K14 * ($C24 / (2 + $N$6)) -> 11155.642 | L24: =L14 * ($C24 / (2 + $N$6)) -> 8581.2632 | ... N24: =N14 * ($C24 / (2 + $N$6)) -> 5077.6705
C26: T E S T C A S E | E26: B I T C O I N I N F I A T | H26: C A P I T A L I N B T C | K26: T V L I N B T C | L26: =H27*(2+N6) -> 19999.998
E27: 100000 | H27: 6666.666
E29: Y E A R 1 | F29: Y E A R 2 | G29: Y E A R 3 | H29: Y E A R 4 | I29: Y E A R 5 | J29: Y E A R 6 | K29: Y E A R 7 | L29: Y E A R 8 | M29: Y E A R 9 | N29: Y E A R 10
B30: B I T C O I N G R O W T H | C30: C U M U L A T I V E F I A T | E30: =E27 + (E27 * E9) -> 130000 | F30: =$E$3 + (E30 * $E$3) + E30 -> 169000.3 | G30: =$E$3 + (F30 * $E$3) + F30 -> 219700.69 | H30: =$E$3 + (G30 * $E$3) + G30 -> 285611.2 | I30: =$E$3 + (H30 * $E$3) + H30 -> 371294.86 | J30: =$E$3 + (I30 * $E$3) + I30 -> 482683.61 | K30: =$E$3 + (J30 * $E$3) + J30 -> 627489 | L30: =$E$3 + (K30 * $E$3) + K30 -> 815736 | M30: =$E$3 + (L30 * $E$3) + L30 -> 1060457.1 | N30: =$E$3 + (M30 * $E$3) + M30 -> 1378594.5
B31: B I T CO I N E X T R A C T I O N | C31: C U M U L A T I V E B T C | E31: =$H$27 * E10 -> 1538.4614 | F31: =$H$27 * F10 -> 2721.8932 | G31: =$H$27 * G10 -> 3632.2254 | H31: =$H$27 * H10 -> 4332.4809 | I31: =$H$27 * I10 -> 4871.139 | J31: =$H$27 * J10 -> 5285.4914 | K31: =$H$27 * K10 -> 5604.224 | L31: =$H$27 * L10 -> 5849.4029 | ... N31: =$H$27 * N10 -> 6183.0784
C32: R E M A I N I N G B T C | E32: =$H$27 * E11 -> 5128.2046 | F32: =$H$27 * F11 -> 3944.7728 | G32: =$H$27 * G11 -> 3034.4406 | H32: =$H$27 * H11 -> 2334.1851 | I32: =$H$27 * I11 -> 1795.527 | J32: =$H$27 * J11 -> 1381.1746 | K32: =$H$27 * K11 -> 1062.442 | L32: =$H$27 * L11 -> 817.26308 | ... N32: =$H$27 * N11 -> 483.58762
B33: B I T C O I N L E A S I N G F E E S A N N U A L I Z E D B T C | C33: S E C U R I T Y | E33: =$H$27 * E12 -> 589.74353 | F33: =$H$27 * F12 -> 453.64887 | G33: =$H$27 * G12 -> 348.96067 | H33: =$H$27 * H12 -> 268.43128 | I33: =$H$27 * I12 -> 206.4856 | J33: =$H$27 * J12 -> 158.83508 | K33: =$H$27 * K12 -> 122.18083 | L33: =$H$27 * L12 -> 93.985254 | ... N33: =$H$27 * N12 -> 55.612576
C34: D E B T | E34: =$H$27 * E13 -> 384.61535 | F34: =$H$27 * F13 -> 295.85796 | G34: =$H$27 * G13 -> 227.58305 | H34: =$H$27 * H13 -> 175.06388 | I34: =$H$27 * I13 -> 134.66452 | J34: =$H$27 * J13 -> 103.5881 | K34: =$H$27 * K13 -> 79.68315 | L34: =$H$27 * L13 -> 61.294731 | ... N34: =$H$27 * N13 -> 36.269072
C35: S E R V I C E | E35: =$H$27 * E14 -> 512.82046 | F35: =$H$27 * F14 -> 394.47728 | G35: =$H$27 * G14 -> 303.44406 | H35: =$H$27 * H14 -> 233.41851 | I35: =$H$27 * I14 -> 179.5527 | J35: =$H$27 * J14 -> 138.11746 | K35: =$H$27 * K14 -> 106.2442 | L35: =$H$27 * L14 -> 81.726308 | ... N35: =$H$27 * N14 -> 48.358762
C36: F E E T O T A L | E36: =$H$27 * E15 -> 1487.1793 | F36: =$H$27 * F15 -> 1143.9841 | G36: =$H$27 * G15 -> 879.98777 | H36: =$H$27 * H15 -> 676.91367 | I36: =$H$27 * I15 -> 520.70282 | J36: =$H$27 * J15 -> 400.54063 | K36: =$H$27 * K15 -> 308.10818 | L36: =$H$27 * L15 -> 237.00629 | ... N36: =$H$27 * N15 -> 140.24041
B37: B I T C O I N L E A S I N G Y I E L D A N N U A L I Z E D B T C | C37: G R O W T H | E37: =$H$27 * E16 -> 3076.9228 | F37: =$H$27 * F16 -> 2366.8637 | G37: =$H$27 * G16 -> 1820.6644 | H37: =$H$27 * H16 -> 1400.511 | I37: =$H$27 * I16 -> 1077.3162 | J37: =$H$27 * J16 -> 828.70476 | K37: =$H$27 * K16 -> 637.4652 | L37: =$H$27 * L16 -> 490.35785 | ... N37: =$H$27 * N16 -> 290.15257
C38: L I Q U I D I T Y | E38: =$H$27 * E17 -> 184.61537 | F38: =$H$27 * F17 -> 172.78105 | G38: =$H$27 * G17 -> 163.67773 | H38: =$H$27 * H17 -> 156.67517 | I38: =$H$27 * I17 -> 151.28859 | J38: =$H$27 * J17 -> 147.14507 | K38: =$H$27 * K17 -> 143.95774 | L38: =$H$27 * L17 -> 141.50595 | ... N38: =$H$27 * N17 -> 138.1692
C39: T R A N S A C T I O N | E39: =$H$27 * E18 -> 92.307683 | F39: =$H$27 * F18 -> 86.390524 | G39: =$H$27 * G18 -> 81.838863 | H39: =$H$27 * H18 -> 78.337585 | I39: =$H$27 * I18 -> 75.644295 | J39: =$H$27 * J18 -> 73.572533 | K39: =$H$27 * K18 -> 71.97887 | L39: =$H$27 * L18 -> 70.752975 | ... N39: =$H$27 * N18 -> 69.084598
C40: G R O S S T O T A L | E40: =$H$27 * E19 -> 3353.8458 | F40: =$H$27 * F19 -> 2626.0352 | G40: =$H$27 * G19 -> 2066.1809 | H40: =$H$27 * H19 -> 1635.5238 | I40: =$H$27 * I19 -> 1304.2491 | J40: =$H$27 * J19 -> 1049.4224 | K40: =$H$27 * K19 -> 853.40181 | L40: =$H$27 * L19 -> 702.61677 | ... N40: =$H$27 * N19 -> 497.40637
C41: N E T T O T A L | E41: =$H$27 * E20 -> 1866.6665 | F41: =$H$27 * F20 -> 1482.0511 | G41: =$H$27 * G20 -> 1186.1932 | H41: =$H$27 * H20 -> 958.61013 | I41: =$H$27 * I20 -> 783.54625 | J41: =$H$27 * J20 -> 648.88173 | K41: =$H$27 * K20 -> 545.29363 | L41: =$H$27 * L20 -> 465.61048 | ... N41: =$H$27 * N20 -> 357.16596

Sheet 3.5X
B2: A M P L I F Y Y O U R B I T C O I N O N T H E L I G H T N I N G N E T W O R K | C2: B I T C O I N L E A S I N G Y I E L D A N N U A L I Z E D F I A T O R B T C | E2: G R O W T H | H2: L I Q U I D I T Y | K2: T R A N S A C T I O N | N2: D E B T L E A S E T O C A P I T A L
E3: =SHARED_VARIABLES!H5 -> 0.3 | H3: =SHARED_VARIABLES!L5 -> 0.01 | K3: =SHARED_VARIABLES!P5 -> 0.005
C5: B I T C O I N L E A S I N G F E E S A N N U A L I Z E D F I A T | E5: S E C U R I T Y | H5: D E B T | K5: S E R V I C E
E6: =SHARED_VARIABLES!H8 -> 0.115 | H6: =SHARED_VARIABLES!L8 -> 0.075 | K6: =SHARED_VARIABLES!P8 -> 0.05 | N6: =SHARED_VARIABLES!L12 -> 1.5
E8: Y E A R 1 | F8: Y E A R 2 | G8: Y E A R 3 | H8: Y E A R 4 | I8: Y E A R 5 | J8: Y E A R 6 | K8: Y E A R 7 | L8: Y E A R 8 | M8: Y E A R 9 | N8: Y E A R 10
B9: B I T C O I N G R O W T H | C9: C U M U L A T I V E F I A T | E9: =$E$3 -> 0.3 | F9: =$E$3 + (E9 * $E$3) + E9 -> 0.69 | G9: =$E$3 + (F9 * $E$3) + F9 -> 1.197 | H9: =$E$3 + (G9 * $E$3) + G9 -> 1.8561 | I9: =$E$3 + (H9 * $E$3) + H9 -> 2.71293 | J9: =$E$3 + (I9 * $E$3) + I9 -> 3.826809 | K9: =$E$3 + (J9 * $E$3) + J9 -> 5.2748517 | L9: =$E$3 + (K9 * $E$3) + K9 -> 7.1573072 | M9: =$E$3 + (L9 * $E$3) + L9 -> 9.6044994 | N9: =$E$3 + (M9 * $E$3) + M9 -> 12.785849
B10: B I T CO I N E X T R A C T I O N | C10: C U M U L A T I V E B T C | E10: =((1 + E9) - 1) / (1 + E9) -> 0.23076923 | F10: =((1 + F9) - 1) / (1 + F9) -> 0.40828402 | G10: =((1 + G9) - 1) / (1 + G9) -> 0.54483386 | H10: =((1 + H9) - 1) / (1 + H9) -> 0.6498722 | I10: =((1 + I9) - 1) / (1 + I9) -> 0.73067093 | J10: =((1 + J9) - 1) / (1 + J9) -> 0.79282379 | K10: =((1 + K9) - 1) / (1 + K9) -> 0.84063368 | L10: =((1 + L9) - 1) / (1 + L9) -> 0.87741053 | ... N10: =((1 + N9) - 1) / (1 + N9) -> 0.92746185
C11: R E M A I N I N G B T C | E11: =1 - E10 -> 0.76923077 | F11: =1 - F10 -> 0.59171598 | G11: =1 - G10 -> 0.45516614 | H11: =1 - H10 -> 0.3501278 | I11: =1 - I10 -> 0.26932907 | J11: =1 - J10 -> 0.20717621 | K11: =1 - K10 -> 0.15936632 | L11: =1 - L10 -> 0.12258947 | ... N11: =1 - N10 -> 0.07253815
B12: B I T C O I N L E A S I N G F E E S A N N U A L I Z E D B T C | C12: S E C U R I T Y | E12: =$E$6 * E11 -> 0.088461538 | F12: =$E$6 * F11 -> 0.068047337 | G12: =$E$6 * G11 -> 0.052344106 | H12: =$E$6 * H11 -> 0.040264697 | I12: =$E$6 * I11 -> 0.030972844 | J12: =$E$6 * J11 -> 0.023825264 | K12: =$E$6 * K11 -> 0.018327126 | L12: =$E$6 * L11 -> 0.01409779 | ... N12: =$E$6 * N11 -> 0.0083418873
C13: D E B T | E13: =$H$6 * $N$6 * E11 -> 0.086538462 | F13: =$H$6 * $N$6 * F11 -> 0.066568047 | G13: =$H$6 * $N$6 * G11 -> 0.05120619 | H13: =$H$6 * $N$6 * H11 -> 0.039389377 | I13: =$H$6 * $N$6 * I11 -> 0.030299521 | J13: =$H$6 * $N$6 * J11 -> 0.023307324 | K13: =$H$6 * $N$6 * K11 -> 0.017928711 | L13: =$H$6 * $N$6 * L11 -> 0.013791316 | ... N13: =$H$6 * $N$6 * N11 -> 0.0081605419
C14: S E R V I C E | E14: =($K$6 * E11) + ($K$6 * $N$6 * E11) -> 0.096153846 | F14: =($K$6 * F11) + ($K$6 * $N$6 * F11) -> 0.073964497 | G14: =($K$6 * G11) + ($K$6 * $N$6 * G11) -> 0.056895767 | H14: =($K$6 * H11) + ($K$6 * $N$6 * H11) -> 0.043765975 | I14: =($K$6 * I11) + ($K$6 * $N$6 * I11) -> 0.033666134 | J14: =($K$6 * J11) + ($K$6 * $N$6 * J11) -> 0.025897026 | K14: =($K$6 * K11) + ($K$6 * $N$6 * K11) -> 0.01992079 | L14: =($K$6 * L11) + ($K$6 * $N$6 * L11) -> 0.015323684 | ... N14: =($K$6 * N11) + ($K$6 * $N$6 * N11) -> 0.0090672688
C15: F E E T O T A L | E15: =SUM(E12:E14) -> 0.27115385 | F15: =SUM(F12:F14) -> 0.20857988 | G15: =SUM(G12:G14) -> 0.16044606 | H15: =SUM(H12:H14) -> 0.12342005 | I15: =SUM(I12:I14) -> 0.094938499 | J15: =SUM(J12:J14) -> 0.073029614 | K15: =SUM(K12:K14) -> 0.056176626 | L15: =SUM(L12:L14) -> 0.04321279 | ... N15: =SUM(N12:N14) -> 0.025569698
B16: B I T C O I N L E A S I N G Y I E L D A N N U A L I Z E D B T C | C16: G R O W T H | E16: =E10 * (1 + $N$6) -> 0.57692308 | F16: =(F10 - E10) * (1 + $N$6) -> 0.44378698 | G16: =(G10 - F10) * (1 + $N$6) -> 0.3413746 | H16: =(H10 - G10) * (1 + $N$6) -> 0.26259585 | I16: =(I10 - H10) * (1 + $N$6) -> 0.20199681 | J16: =(J10 - I10) * (1 + $N$6) -> 0.15538216 | K16: =(K10 - J10) * (1 + $N$6) -> 0.11952474 | L16: =(L10 - K10) * (1 + $N$6) -> 0.091942105 | M16: =(M10 - L10) * (1 + $N$6) -> 0.070724697 | N16: =(N10 - M10) * (1 + $N$6) -> 0.054403613
C17: L I Q U I D I T Y | E17: =((1 + $N$6) * $H$3) + ($H$3 * E11) -> 0.032692308 | F17: =((1 + $N$6) * $H$3) + ($H$3 * F11) -> 0.03091716 | G17: =((1 + $N$6) * $H$3) + ($H$3 * G11) -> 0.029551661 | H17: =((1 + $N$6) * $H$3) + ($H$3 * H11) -> 0.028501278 | I17: =((1 + $N$6) * $H$3) + ($H$3 * I11) -> 0.027693291 | J17: =((1 + $N$6) * $H$3) + ($H$3 * J11) -> 0.027071762 | K17: =((1 + $N$6) * $H$3) + ($H$3 * K11) -> 0.026593663 | L17: =((1 + $N$6) * $H$3) + ($H$3 * L11) -> 0.026225895 | ... N17: =((1 + $N$6) * $H$3) + ($H$3 * N11) -> 0.025725382
C18: T R A N S A C T I O N | E18: =((1 + $N$6) * $K$3) + ($K$3 * E11) -> 0.016346154 | F18: =((1 + $N$6) * $K$3) + ($K$3 * F11) -> 0.01545858 | G18: =((1 + $N$6) * $K$3) + ($K$3 * G11) -> 0.014775831 | H18: =((1 + $N$6) * $K$3) + ($K$3 * H11) -> 0.014250639 | I18: =((1 + $N$6) * $K$3) + ($K$3 * I11) -> 0.013846645 | J18: =((1 + $N$6) * $K$3) + ($K$3 * J11) -> 0.013535881 | K18: =((1 + $N$6) * $K$3) + ($K$3 * K11) -> 0.013296832 | L18: =((1 + $N$6) * $K$3) + ($K$3 * L11) -> 0.013112947 | ... N18: =((1 + $N$6) * $K$3) + ($K$3 * N11) -> 0.012862691
C19: G R O S S T O T A L | E19: =SUM(E16:E18) -> 0.62596154 | F19: =SUM(F16:F18) -> 0.49016272 | G19: =SUM(G16:G18) -> 0.38570209 | H19: =SUM(H16:H18) -> 0.30534776 | I19: =SUM(I16:I18) -> 0.24353674 | J19: =SUM(J16:J18) -> 0.1959898 | K19: =SUM(K16:K18) -> 0.15941523 | L19: =SUM(L16:L18) -> 0.13128095 | ... N19: =SUM(N16:N18) -> 0.092991685
C20: N E T T O T A L | E20: =E19 - E15 -> 0.35480769 | F20: =F19 - F15 -> 0.28158284 | G20: =G19 - G15 -> 0.22525603 | H20: =H19 - H15 -> 0.18192772 | I20: =I19 - I15 -> 0.14859824 | J20: =J19 - J15 -> 0.12296019 | K20: =K19 - K15 -> 0.10323861 | L20: =L19 - L15 -> 0.088068158 | ... N20: =N19 - N15 -> 0.067421987
B21: B I T C O I N T V L R E V E N U E A N N U A L I Z E D B T C | C21: 20000 | E21: =E14 * ($C21 / (2 + $N$6)) -> 549.45055 | F21: =F14 * ($C21 / (2 + $N$6)) -> 422.65427 | G21: =G14 * ($C21 / (2 + $N$6)) -> 325.11867 | H21: =H14 * ($C21 / (2 + $N$6)) -> 250.09128 | I21: =I14 * ($C21 / (2 + $N$6)) -> 192.37791 | J21: =J14 * ($C21 / (2 + $N$6)) -> 147.98301 | K21: =K14 * ($C21 / (2 + $N$6)) -> 113.83308 | L21: =L14 * ($C21 / (2 + $N$6)) -> 87.56391 | ... N21: =N14 * ($C21 / (2 + $N$6)) -> 51.812964
C22: 400000 | E22: =E14 * ($C22 / (2 + $N$6)) -> 10989.011 | F22: =F14 * ($C22 / (2 + $N$6)) -> 8453.0854 | G22: =G14 * ($C22 / (2 + $N$6)) -> 6502.3734 | H22: =H14 * ($C22 / (2 + $N$6)) -> 5001.8257 | I22: =I14 * ($C22 / (2 + $N$6)) -> 3847.5582 | J22: =J14 * ($C22 / (2 + $N$6)) -> 2959.6602 | K22: =K14 * ($C22 / (2 + $N$6)) -> 2276.6617 | L22: =L14 * ($C22 / (2 + $N$6)) -> 1751.2782 | ... N22: =N14 * ($C22 / (2 + $N$6)) -> 1036.2593
C23: 1000000 | E23: =E14 * ($C23 / (2 + $N$6)) -> 27472.527 | F23: =F14 * ($C23 / (2 + $N$6)) -> 21132.713 | G23: =G14 * ($C23 / (2 + $N$6)) -> 16255.933 | H23: =H14 * ($C23 / (2 + $N$6)) -> 12504.564 | I23: =I14 * ($C23 / (2 + $N$6)) -> 9618.8955 | J23: =J14 * ($C23 / (2 + $N$6)) -> 7399.1504 | K23: =K14 * ($C23 / (2 + $N$6)) -> 5691.6541 | L23: =L14 * ($C23 / (2 + $N$6)) -> 4378.1955 | ... N23: =N14 * ($C23 / (2 + $N$6)) -> 2590.6482
C24: 2100000 | E24: =E14 * ($C24 / (2 + $N$6)) -> 57692.308 | F24: =F14 * ($C24 / (2 + $N$6)) -> 44378.698 | G24: =G14 * ($C24 / (2 + $N$6)) -> 34137.46 | H24: =H14 * ($C24 / (2 + $N$6)) -> 26259.585 | I24: =I14 * ($C24 / (2 + $N$6)) -> 20199.681 | J24: =J14 * ($C24 / (2 + $N$6)) -> 15538.216 | K24: =K14 * ($C24 / (2 + $N$6)) -> 11952.474 | L24: =L14 * ($C24 / (2 + $N$6)) -> 9194.2105 | ... N24: =N14 * ($C24 / (2 + $N$6)) -> 5440.3613
C26: T E S T C A S E | E26: B I T C O I N I N F I A T | H26: C A P I T A L I N B T C | K26: T V L I N B T C | L26: =H27*(2+N6) -> 19999.98
E27: 100000 | H27: 5714.28
E29: Y E A R 1 | F29: Y E A R 2 | G29: Y E A R 3 | H29: Y E A R 4 | I29: Y E A R 5 | J29: Y E A R 6 | K29: Y E A R 7 | L29: Y E A R 8 | M29: Y E A R 9 | N29: Y E A R 10
B30: B I T C O I N G R O W T H | C30: C U M U L A T I V E F I A T | E30: =E27 + (E27 * E9) -> 130000 | F30: =$E$3 + (E30 * $E$3) + E30 -> 169000.3 | G30: =$E$3 + (F30 * $E$3) + F30 -> 219700.69 | H30: =$E$3 + (G30 * $E$3) + G30 -> 285611.2 | I30: =$E$3 + (H30 * $E$3) + H30 -> 371294.86 | J30: =$E$3 + (I30 * $E$3) + I30 -> 482683.61 | K30: =$E$3 + (J30 * $E$3) + J30 -> 627489 | L30: =$E$3 + (K30 * $E$3) + K30 -> 815736 | M30: =$E$3 + (L30 * $E$3) + L30 -> 1060457.1 | N30: =$E$3 + (M30 * $E$3) + M30 -> 1378594.5
