Workbook

Sheet YIELD_CALCULATOR
B2: Bitcoin Lightning Credit Derivatives A permissionless, decentralized and distributed strategy for ultra-high yields using leveraged bitcoin growth and lightning transaction fee exposure | D2: Bitcoin Yield Estimate Variables BiGY = Bitcoin Growth Yield (CAGR) BiLY = Bitcoin Liquidity Yield BiTY = Bitcoin Transaction Yield | G2: Bitcoin Yield Estimate 5 Year Summary SR = Stable Receiver SB = Stable Balancer SP = Stable Provider | K2: Lightning Bank 5 Year Revenue Summary TVL = Total Value Locked
K3: Bitcoin TVL | L3: Measure | M3: BTC | N3: USD
D4: Bitcoin USD Price Start | E4: 100000 | G4: SR USD Comp. | H4: Annual Avg. % | I4: =I43 -> 0.271293 | K4: =C127 -> 20000 | L4: Annual Avg. | M4: =I128 -> 243.55698 | N4: =M4*$I$15 -> 90431000
D5: Annual Bitcoin Growth Yield % | E5: 0.3 | G5: SP BiGY BTC | H5: Annual Avg. % | I5: =I67 -> 0.14613419 | K5: =C127 -> 20000 | L5: Cumulative | M5: =I129 -> 1217.7849 | N5: =M5*$I$15 -> 4.52155e+08
D6: Annual Bitcoin Liquidity Yield % | E6: 0.02 | G6: SP BiLY BTC | H6: Annual Avg. % | I6: =I80 -> 0.029742279 | K6: =C130 -> 400000 | L6: Annual Avg. | M6: =I131 -> 4871.1395 | N6: =M6*$I$15 -> 1.80862e+09
D7: Annual Bitcoin Transaction Yield % | E7: 0.01 | G7: SP BiTY BTC | H7: Annual Avg. % | I7: =I95 -> 0.01487114 | K7: =C130 -> 400000 | L7: Cumulative | M7: =I132 -> 24355.698 | N7: =M7*$I$15 -> 9043100000
D8: Stable Receiver Security Annual USD % | E8: 0.15 | G8: SP BiLY SR BTC | H8: Annual Avg. % | I8: =-I35 -> -0.073067093 | K8: =C133 -> 1000000 | L8: Annual Avg. | M8: =I134 -> 12177.849 | N8: =M8*$I$15 -> 4521550000
D9: Stable Balancer Security Annual USD % | E9: 0.05 | G9: SP BiLY SB BTC | H9: Annual Avg. % | I9: =-I51 -> -0.024355698 | K9: =C133 -> 1000000 | L9: Cumulative | M9: =I135 -> 60889.244 | N9: =M9*$I$15 -> 22607750000
D10: Stable Balancer Debt Annual USD % | E10: 0.075 | G10: SP Total BTC | H10: Annual Avg. % | I10: =I110 -> 0.093324814
D11: Stable Provider Debt-to-Value % | E11: 0
B13: Yield Estimate Calculator | C13: Unit of Account | D13: Measure | E13: Year 1 | F13: Year 2 | G13: Year 3 | H13: Year 4 | I13: Year 5 | J13: Year 6 | K13: Year 7 | L13: Year 8 | M13: Year 9 | N13: Year 10
B15: Bitcoin | C15: USD | D15: Price | E15: =($E$4 * $E$5) + $E$4 -> 130000 | F15: =(E15 * $E$5) + E15 -> 169000 | G15: =(F15 * $E$5) + F15 -> 219700 | H15: =(G15 * $E$5) + G15 -> 285610 | I15: =(H15 * $E$5) + H15 -> 371293 | J15: =(I15 * $E$5) + I15 -> 482680.9 | K15: =(J15 * $E$5) + J15 -> 627485.17 | L15: =(K15 * $E$5) + K15 -> 815730.72 | M15: =(L15 * $E$5) + L15 -> 1060449.9 | N15: =(M15 * $E$5) + M15 -> 1378584.9
D16: Marketcap | E16: =E15*21000000 -> 2730000000000 | F16: =F15*21000000 -> 3549000000000 | G16: =G15*21000000 -> 4613700000000 | H16: =H15*21000000 -> 5997810000000 | I16: =I15*21000000 -> 7797153000000 | J16: =J15*21000000 -> 10136298900000 | K16: =K15*21000000 -> 13177188570000 | L16: =L15*21000000 -> 17130345141000 | ... N16: =N15*21000000 -> 28950283288290
B17: Bitcoin Growth Yield (BiGY) | C17: BTC | D17: Stable Security Cumulative % | E17: =(E15-$E4)/E15 -> 0.23076923 | F17: =(F15-$E4)/F15 -> 0.40828402 | G17: =(G15-$E4)/G15 -> 0.54483386 | H17: =(H15-$E4)/H15 -> 0.6498722 | I17: =(I15-$E4)/I15 -> 0.73067093 | J17: =(J15-$E4)/J15 -> 0.79282379 | K17: =(K15-$E4)/K15 -> 0.84063368 | L17: =(L15-$E4)/L15 -> 0.87741053 | ... N17: =(N15-$E4)/N15 -> 0.92746185
D18: Stable Security Remaining % | E18: =1-E17 -> 0.76923077 | F18: =1-F17 -> 0.59171598 | G18: =1-G17 -> 0.45516614 | H18: =1-H17 -> 0.3501278 | I18: =1-I17 -> 0.26932907 | J18: =1-J17 -> 0.20717621 | K18: =1-K17 -> 0.15936632 | L18: =1-L17 -> 0.12258947 | ... N18: =1-N17 -> 0.07253815
D19: Stable Security Annual % | E19: =E17 -> 0.23076923 | F19: =F17-E17 -> 0.17751479 | G19: =G17-F17 -> 0.13654984 | H19: =H17-G17 -> 0.10503834 | I19: =I17-H17 -> 0.080798722 | J19: =J17-I17 -> 0.062152863 | K19: =K17-J17 -> 0.047809895 | L19: =L17-K17 -> 0.036776842 | M19: =M17-L17 -> 0.028289879 | N19: =N17-M17 -> 0.021761445
D20: Stable Security Annual Average % | I20: =AVERAGE(E19:I19) -> 0.14613419 | N20: =AVERAGE(E19:N19) -> 0.092746185
D21: Stable Debt Annual % | E21: =$E$11*E19 -> 0 | F21: =$E$11*F19 -> 0 | G21: =$E$11*G19 -> 0 | H21: =$E$11*H19 -> 0 | I21: =$E$11*I19 -> 0 | J21: =$E$11*J19 -> 0 | K21: =$E$11*K19 -> 0 | L21: =$E$11*L19 -> 0 | ... N21: =$E$11*N19 -> 0
D22: Stable Debt Annual Avg. % | I22: =AVERAGE(E21:I21) -> 0 | N22: =AVERAGE(E21:N21) -> 0
D23: Total Annual % | E23: =E19+E21 -> 0.23076923 | F23: =F19+F21 -> 0.17751479 | G23: =G19+G21 -> 0.13654984 | H23: =H19+H21 -> 0.10503834 | I23: =I19+I21 -> 0.080798722 | J23: =J19+J21 -> 0.062152863 | K23: =K19+K21 -> 0.047809895 | L23: =L19+L21 -> 0.036776842 | ... N23: =N19+N21 -> 0.021761445
D24: Total Annual Average % | I24: =AVERAGE(E23:I23) -> 0.14613419 | N24: =AVERAGE(E23:N23) -> 0.092746185
B25: Bitcoin Liquidity Yield (BiLY) | C25: BTC | D25: Annual % | E25: =((1+$E$11)*$E$6)+($E$6*E18) -> 0.035384615 | F25: =((1+$E$11)*$E$6)+($E$6*F18) -> 0.03183432 | G25: =((1+$E$11)*$E$6)+($E$6*G18) -> 0.029103323 | H25: =((1+$E$11)*$E$6)+($E$6*H18) -> 0.027002556 | I25: =((1+$E$11)*$E$6)+($E$6*I18) -> 0.025386581 | J25: =((1+$E$11)*$E$6)+($E$6*J18) -> 0.024143524 | K25: =((1+$E$11)*$E$6)+($E$6*K18) -> 0.023187326 | L25: =((1+$E$11)*$E$6)+($E$6*L18) -> 0.022451789 | ... N25: =((1+$E$11)*$E$6)+($E$6*N18) -> 0.021450763
D26: Annual Average % | I26: =AVERAGE(E25:I25) -> 0.029742279 | N26: =AVERAGE(E25:N25) -> 0.026183079
D27: Cumulative % | E27: =E25 -> 0.035384615 | F27: =E27+F25 -> 0.067218935 | G27: =F27+G25 -> 0.096322258 | H27: =G27+H25 -> 0.12332481 | I27: =H27+I25 -> 0.1487114 | J27: =I27+J25 -> 0.17285492 | K27: =J27+K25 -> 0.19604225 | L27: =K27+L25 -> 0.21849404 | M27: =L27+M25 -> 0.24038003 | N27: =M27+N25 -> 0.26183079
B28: Bitcoin Transaction Yield (BiTY) | C28: BTC | D28: Annual % | E28: =((1+$E$11)*$E$7)+($E$7*E18) -> 0.017692308 | F28: =((1+$E$11)*$E$7)+($E$7*F18) -> 0.01591716 | G28: =((1+$E$11)*$E$7)+($E$7*G18) -> 0.014551661 | H28: =((1+$E$11)*$E$7)+($E$7*H18) -> 0.013501278 | I28: =((1+$E$11)*$E$7)+($E$7*I18) -> 0.012693291 | J28: =((1+$E$11)*$E$7)+($E$7*J18) -> 0.012071762 | K28: =((1+$E$11)*$E$7)+($E$7*K18) -> 0.011593663 | L28: =((1+$E$11)*$E$7)+($E$7*L18) -> 0.011225895 | ... N28: =((1+$E$11)*$E$7)+($E$7*N18) -> 0.010725382
D29: Annual Average % | I29: =AVERAGE(E28:I28) -> 0.01487114 | N29: =AVERAGE(E28:N28) -> 0.013091539
D30: Cumulative % | E30: =E28 -> 0.017692308 | F30: =E30+F28 -> 0.033609467 | G30: =F30+G28 -> 0.048161129 | H30: =G30+H28 -> 0.061662407 | I30: =H30+I28 -> 0.074355698 | J30: =I30+J28 -> 0.08642746 | K30: =J30+K28 -> 0.098021123 | L30: =K30+L28 -> 0.10924702 | M30: =L30+M28 -> 0.12019001 | N30: =M30+N28 -> 0.13091539
B32: Stable Receiver / Fiat Lender | C32: Test Case | D32: ="10 BTC / "&TEXT($E$4*10, "$###0.00,,")&"M USD" -> 10 BTC / $1.00M USD | E32: Year 1 | F32: Year 2 | G32: Year 3 | H32: Year 4 | I32: Year 5 | J32: Year 6 | K32: Year 7 | L32: Year 8 | M32: Year 9 | N32: Year 10
B34: Bitcoin Liquidity Yield (BiLY) | C34: BTC | D34: Total Annual % | E34: =E39*$E$4/E$15 -> 0.11538462 | F34: =F39*$E$4/F$15 -> 0.088757396 | G34: =G39*$E$4/G$15 -> 0.06827492 | H34: =H39*$E$4/H$15 -> 0.052519169 | I34: =I39*$E$4/I$15 -> 0.040399361 | J34: =J39*$E$4/J$15 -> 0.031076432 | K34: =K39*$E$4/K$15 -> 0.023904947 | L34: =L39*$E$4/L$15 -> 0.018388421 | ... N34: =N39*$E$4/N$15 -> 0.010880723
D35: Total Annual Average % | I35: =AVERAGE(E34:I34) -> 0.073067093 | N35: =AVERAGE(E34:N34) -> 0.046373092
D36: Cumulative % | E36: =E$17*(E34/E$19) -> 0.11538462 | F36: =F$17*(F34/F$19) -> 0.20414201 | G36: =G$17*(G34/G$19) -> 0.27241693 | H36: =H$17*(H34/H$19) -> 0.3249361 | I36: =I$17*(I34/I$19) -> 0.36533546 | J36: =J$17*(J34/J$19) -> 0.39641189 | K36: =K$17*(K34/K$19) -> 0.42031684 | L36: =L$17*(L34/L$19) -> 0.43870526 | ... N36: =N$17*(N34/N$19) -> 0.46373092
D37: Test Case Annual | E37: =10*E34 -> 1.1538462 | F37: =10*F34 -> 0.88757396 | G37: =10*G34 -> 0.6827492 | H37: =10*H34 -> 0.52519169 | I37: =10*I34 -> 0.40399361 | J37: =10*J34 -> 0.31076432 | K37: =10*K34 -> 0.23904947 | L37: =10*L34 -> 0.18388421 | ... N37: =10*N34 -> 0.10880723
D38: Test Case Cumulative | E38: =10*E36 -> 1.1538462 | F38: =10*F36 -> 2.0414201 | G38: =10*G36 -> 2.7241693 | H38: =10*H36 -> 3.249361 | I38: =10*I36 -> 3.6533546 | J38: =10*J36 -> 3.9641189 | K38: =10*K36 -> 4.2031684 | L38: =10*L36 -> 4.3870526 | ... N38: =10*N36 -> 4.6373092
C39: USD Simple | D39: Annual % | E39: =E8 -> 0.15 | F39: =E39 -> 0.15 | G39: =F39 -> 0.15 | H39: =G39 -> 0.15 | I39: =H39 -> 0.15 | J39: =I39 -> 0.15 | K39: =J39 -> 0.15 | L39: =K39 -> 0.15 | M39: =L39 -> 0.15 | N39: =M39 -> 0.15
D40: Test Case Annual | E40: =E37*E$15 -> 150000 | F40: =F37*F$15 -> 150000 | G40: =G37*G$15 -> 150000 | H40: =H37*H$15 -> 150000 | I40: =I37*I$15 -> 150000 | J40: =J37*J$15 -> 150000 | K40: =K37*K$15 -> 150000 | L40: =L37*L$15 -> 150000 | ... N40: =N37*N$15 -> 150000
D41: Test Case Cumulative | E41: =E40 -> 150000 | F41: =E41+F40 -> 300000 | G41: =F41+G40 -> 450000 | H41: =G41+H40 -> 600000 | I41: =H41+I40 -> 750000 | J41: =I41+J40 -> 900000 | K41: =J41+K40 -> 1050000 | L41: =K41+L40 -> 1200000 | M41: =L41+M40 -> 1350000 | N41: =M41+N40 -> 1500000
C42: USD Compounded | D42: Annual % | E42: =E36*E$15/$E$4 -> 0.15 | F42: =F36*F$15/$E$4-E42 -> 0.195 | G42: =G36*G$15/$E$4-F42-E42 -> 0.2535 | H42: =H36*H$15/$E$4-G42-F42-E42 -> 0.32955 | I42: =I36*I$15/$E$4-H42-G42-F42-E42 -> 0.428415 | J42: =J36*J$15/$E$4-I42-H42-G42-F42-E42 -> 0.5569395 | K42: =K36*K$15/$E$4-J42-I42-H42-G42-F42-E42 -> 0.72402135 | L42: =L36*L$15/$E$4-K42-J42-I42-H42-G42-F42-E42 -> 0.94122775 | M42: =M36*M$15/$E$4-L42-K42-J42-I42-H42-G42-F42-E42 -> 1.2235961 | N42: =N36*N$15/$E$4-M42-L42-K42-J42-I42-H42-G42-F42-E42 -> 1.5906749
D43: Annual Average % | I43: =AVERAGE(E42:I42) -> 0.271293 | N43: =AVERAGE(E42:N42) -> 0.63929246
D44: Test Case Annual | E44: =E46 -> 150000 | F44: =F46-E46 -> 195000 | G44: =G46-F46 -> 253500 | H44: =H46-G46 -> 329550 | I44: =I46-H46 -> 428415 | J44: =J46-I46 -> 556939.5 | K44: =K46-J46 -> 724021.35 | L44: =L46-K46 -> 941227.75 | M44: =M46-L46 -> 1223596.1 | N44: =N46-M46 -> 1590674.9
D45: Test Case Annual Average | I45: =AVERAGE(E44:I44) -> 271293 | N45: =AVERAGE(E44:N44) -> 639292.46
...

Sheet YIELD_BURNDOWN
B2: Bitcoin Lightning Credit Derivatives A permissionless, decentralized and distributed strategy for ultra-high yields using leveraged bitcoin growth and lightning transaction fee exposure | C2: Bitcoin Yield Estimate Variables | F2: Bitcoin Compound Annual Growth Rate Calculator
C4: Bitcoin USD Price Start | D4: 100000 | F4: Start Price | I4: 57885.44
F5: Start Date | I5: 44519
F6: End Price | I6: 89588.18
F7: End Date | I7: 45980
F8: Compound Annual Growth Rate | I8: =(I6/I4)^(1/DATEDIF(I5,I7,"Y"))-1 -> 0.11537356
B10: Bitcoin Yield Estimate 10 Year Burndown Summary | D10: Year 1 | E10: Year 2 | F10: Year 3 | G10: Year 4 | H10: Year 5 | I10: Year 6 | J10: Year 7 | K10: Year 8 | L10: Year 9 | M10: Year 10
B11: Bitcoin Compound Annual Growth Rate (CAGR) | C11: Measure
B12: 0.2 | C12: Bitcoin USD Price | D12: =($D$4 * $B12) + $D$4 -> 120000 | E12: =(D12 * $B12) + D12 -> 144000 | F12: =(E12 * $B12) + E12 -> 172800 | G12: =(F12 * $B12) + F12 -> 207360 | H12: =(G12 * $B12) + G12 -> 248832 | I12: =(H12 * $B12) + H12 -> 298598.4 | J12: =(I12 * $B12) + I12 -> 358318.08 | K12: =(J12 * $B12) + J12 -> 429981.7 | L12: =(K12 * $B12) + K12 -> 515978.04 | M12: =(L12 * $B12) + L12 -> 619173.64
C13: Bitcoin USD Marketcap | D13: =D12*21000000 -> 2520000000000 | E13: =E12*21000000 -> 3024000000000 | F13: =F12*21000000 -> 3628800000000 | G13: =G12*21000000 -> 4354560000000 | H13: =H12*21000000 -> 5225472000000 | I13: =I12*21000000 -> 6.2705664e+12 | J13: =J12*21000000 -> 7524679680000 | K13: =K12*21000000 -> 9029615616000 | ... M13: =M12*21000000 -> 13002646487040
C14: Cumulative BTC Yield % | D14: =( ( D12 - $D$4 ) ) / D12 -> 0.16666667 | E14: =( ( E12 - $D$4 ) ) / E12 -> 0.30555556 | F14: =( ( F12 - $D$4 ) ) / F12 -> 0.4212963 | G14: =( ( G12 - $D$4 ) ) / G12 -> 0.51774691 | H14: =( ( H12 - $D$4 ) ) / H12 -> 0.59812243 | I14: =( ( I12 - $D$4 ) ) / I12 -> 0.66510202 | J14: =( ( J12 - $D$4 ) ) / J12 -> 0.72091835 | K14: =( ( K12 - $D$4 ) ) / K12 -> 0.76743196 | ... M14: =( ( M12 - $D$4 ) ) / M12 -> 0.83849442
C15: Remaining BTC Yield % | D15: =1-D14 -> 0.83333333 | E15: =1-E14 -> 0.69444444 | F15: =1-F14 -> 0.5787037 | G15: =1-G14 -> 0.48225309 | H15: =1-H14 -> 0.40187757 | I15: =1-I14 -> 0.33489798 | J15: =1-J14 -> 0.27908165 | K15: =1-K14 -> 0.23256804 | ... M15: =1-M14 -> 0.16150558
C16: Annual BTC Yield % | D16: =D14 -> 0.16666667 | E16: =E14-D14 -> 0.13888889 | F16: =F14-E14 -> 0.11574074 | G16: =G14-F14 -> 0.096450617 | H16: =H14-G14 -> 0.080375514 | I16: =I14-H14 -> 0.066979595 | J16: =J14-I14 -> 0.055816329 | K16: =K14-J14 -> 0.046513608 | L16: =L14-K14 -> 0.03876134 | M16: =M14-L14 -> 0.032301117
C17: Annual Average BTC Yield % | H17: =SUM(D16:H16)/5 -> 0.11962449 | M17: =SUM(D16:M16)/10 -> 0.083849442
B18: 0.25 | C18: Bitcoin USD Price | D18: =($D$4 * $B18) + $D$4 -> 125000 | E18: =(D18 * $B18) + D18 -> 156250 | F18: =(E18 * $B18) + E18 -> 195312.5 | G18: =(F18 * $B18) + F18 -> 244140.62 | H18: =(G18 * $B18) + G18 -> 305175.78 | I18: =(H18 * $B18) + H18 -> 381469.73 | J18: =(I18 * $B18) + I18 -> 476837.16 | K18: =(J18 * $B18) + J18 -> 596046.45 | L18: =(K18 * $B18) + K18 -> 745058.06 | M18: =(L18 * $B18) + L18 -> 931322.57
C19: Bitcoin USD Marketcap | D19: =D18*21000000 -> 2625000000000 | E19: =E18*21000000 -> 3281250000000 | F19: =F18*21000000 -> 4101562500000 | G19: =G18*21000000 -> 5126953125000 | H19: =H18*21000000 -> 6408691406250 | I19: =I18*21000000 -> 8.0108643e+12 | J19: =J18*21000000 -> 1.001358e+13 | K19: =K18*21000000 -> 1.2516975e+13 | ... M19: =M18*21000000 -> 1.9557774e+13
C20: Cumulative BTC Yield % | D20: =( ( D18 - $D$4 ) ) / D18 -> 0.2 | E20: =( ( E18 - $D$4 ) ) / E18 -> 0.36 | F20: =( ( F18 - $D$4 ) ) / F18 -> 0.488 | G20: =( ( G18 - $D$4 ) ) / G18 -> 0.5904 | H20: =( ( H18 - $D$4 ) ) / H18 -> 0.67232 | I20: =( ( I18 - $D$4 ) ) / I18 -> 0.737856 | J20: =( ( J18 - $D$4 ) ) / J18 -> 0.7902848 | K20: =( ( K18 - $D$4 ) ) / K18 -> 0.83222784 | ... M20: =( ( M18 - $D$4 ) ) / M18 -> 0.89262582
C21: Remaining BTC Yield % | D21: =1-D20 -> 0.8 | E21: =1-E20 -> 0.64 | F21: =1-F20 -> 0.512 | G21: =1-G20 -> 0.4096 | H21: =1-H20 -> 0.32768 | I21: =1-I20 -> 0.262144 | J21: =1-J20 -> 0.2097152 | K21: =1-K20 -> 0.16777216 | ... M21: =1-M20 -> 0.10737418
C22: Annual BTC Yield % | D22: =D20 -> 0.2 | E22: =E20-D20 -> 0.16 | F22: =F20-E20 -> 0.128 | G22: =G20-F20 -> 0.1024 | H22: =H20-G20 -> 0.08192 | I22: =I20-H20 -> 0.065536 | J22: =J20-I20 -> 0.0524288 | K22: =K20-J20 -> 0.04194304 | L22: =L20-K20 -> 0.033554432 | M22: =M20-L20 -> 0.026843546
C23: Annual Average BTC Yield % | H23: =SUM(D22:H22)/5 -> 0.134464 | M23: =SUM(D22:M22)/10 -> 0.089262582
B24: 0.3 | C24: Bitcoin USD Price | D24: =($D$4 * $B24) + $D$4 -> 130000 | E24: =(D24 * $B24) + D24 -> 169000 | F24: =(E24 * $B24) + E24 -> 219700 | G24: =(F24 * $B24) + F24 -> 285610 | H24: =(G24 * $B24) + G24 -> 371293 | I24: =(H24 * $B24) + H24 -> 482680.9 | J24: =(I24 * $B24) + I24 -> 627485.17 | K24: =(J24 * $B24) + J24 -> 815730.72 | L24: =(K24 * $B24) + K24 -> 1060449.9 | M24: =(L24 * $B24) + L24 -> 1378584.9
C25: Bitcoin USD Marketcap | D25: =D24*21000000 -> 2730000000000 | E25: =E24*21000000 -> 3549000000000 | F25: =F24*21000000 -> 4613700000000 | G25: =G24*21000000 -> 5997810000000 | H25: =H24*21000000 -> 7797153000000 | I25: =I24*21000000 -> 10136298900000 | J25: =J24*21000000 -> 13177188570000 | K25: =K24*21000000 -> 17130345141000 | ... M25: =M24*21000000 -> 28950283288290
C26: Cumulative BTC Yield % | D26: =( ( D24 - $D$4 ) ) / D24 -> 0.23076923 | E26: =( ( E24 - $D$4 ) ) / E24 -> 0.40828402 | F26: =( ( F24 - $D$4 ) ) / F24 -> 0.54483386 | G26: =( ( G24 - $D$4 ) ) / G24 -> 0.6498722 | H26: =( ( H24 - $D$4 ) ) / H24 -> 0.73067093 | I26: =( ( I24 - $D$4 ) ) / I24 -> 0.79282379 | J26: =( ( J24 - $D$4 ) ) / J24 -> 0.84063368 | K26: =( ( K24 - $D$4 ) ) / K24 -> 0.87741053 | ... M26: =( ( M24 - $D$4 ) ) / M24 -> 0.92746185
C27: Remaining BTC Yield % | D27: =1-D26 -> 0.76923077 | E27: =1-E26 -> 0.59171598 | F27: =1-F26 -> 0.45516614 | G27: =1-G26 -> 0.3501278 | H27: =1-H26 -> 0.26932907 | I27: =1-I26 -> 0.20717621 | J27: =1-J26 -> 0.15936632 | K27: =1-K26 -> 0.12258947 | ... M27: =1-M26 -> 0.07253815
C28: Annual BTC Yield % | D28: =D26 -> 0.23076923 | E28: =E26-D26 -> 0.17751479 | F28: =F26-E26 -> 0.13654984 | G28: =G26-F26 -> 0.10503834 | H28: =H26-G26 -> 0.080798722 | I28: =I26-H26 -> 0.062152863 | J28: =J26-I26 -> 0.047809895 | K28: =K26-J26 -> 0.036776842 | L28: =L26-K26 -> 0.028289879 | M28: =M26-L26 -> 0.021761445
C29: Annual Average BTC Yield % | H29: =SUM(D28:H28)/5 -> 0.14613419 | M29: =SUM(D28:M28)/10 -> 0.092746185
B30: 0.35 | C30: Bitcoin USD Price | D30: =($D$4 * $B30) + $D$4 -> 135000 | E30: =(D30 * $B30) + D30 -> 182250 | F30: =(E30 * $B30) + E30 -> 246037.5 | G30: =(F30 * $B30) + F30 -> 332150.62 | H30: =(G30 * $B30) + G30 -> 448403.34 | I30: =(H30 * $B30) + H30 -> 605344.51 | J30: =(I30 * $B30) + I30 -> 817215.09 | K30: =(J30 * $B30) + J30 -> 1103240.4 | L30: =(K30 * $B30) + K30 -> 1489374.5 | M30: =(L30 * $B30) + L30 -> 2010655.6
C31: Bitcoin USD Marketcap | D31: =D30*21000000 -> 2835000000000 | E31: =E30*21000000 -> 3827250000000 | F31: =F30*21000000 -> 5166787500000 | G31: =G30*21000000 -> 6975163125000 | H31: =H30*21000000 -> 9416470218750 | I31: =I30*21000000 -> 1.2712235e+13 | J31: =J30*21000000 -> 1.7161517e+13 | K31: =K30*21000000 -> 2.3168048e+13 | ... M31: =M30*21000000 -> 4.2223767e+13
C32: Cumulative BTC Yield % | D32: =( ( D30 - $D$4 ) ) / D30 -> 0.25925926 | E32: =( ( E30 - $D$4 ) ) / E30 -> 0.45130316 | F32: =( ( F30 - $D$4 ) ) / F30 -> 0.59355789 | G32: =( ( G30 - $D$4 ) ) / G30 -> 0.69893177 | H32: =( ( H30 - $D$4 ) ) / H30 -> 0.7769865 | I32: =( ( I30 - $D$4 ) ) / I30 -> 0.83480481 | J32: =( ( J30 - $D$4 ) ) / J30 -> 0.8776332 | K32: =( ( K30 - $D$4 ) ) / K30 -> 0.90935792 | ... M32: =( ( M30 - $D$4 ) ) / M30 -> 0.95026498
C33: Remaining BTC Yield % | D33: =1-D32 -> 0.74074074 | E33: =1-E32 -> 0.54869684 | F33: =1-F32 -> 0.40644211 | G33: =1-G32 -> 0.30106823 | H33: =1-H32 -> 0.2230135 | I33: =1-I32 -> 0.16519519 | J33: =1-J32 -> 0.1223668 | K33: =1-K32 -> 0.090642078 | ... M33: =1-M32 -> 0.049735022
C34: Annual BTC Yield % | D34: =D32 -> 0.25925926 | E34: =E32-D32 -> 0.1920439 | F34: =F32-E32 -> 0.14225474 | G34: =G32-F32 -> 0.10537388 | H34: =H32-G32 -> 0.078054726 | I34: =I32-H32 -> 0.057818315 | J34: =J32-I32 -> 0.042828382 | K34: =K32-J32 -> 0.031724727 | L34: =L32-K32 -> 0.023499798 | M34: =M32-L32 -> 0.017407258
C35: Annual Average BTC Yield % | H35: =SUM(D34:H34)/5 -> 0.1553973 | M35: =SUM(D34:M34)/10 -> 0.095026498
B36: 0.4 | C36: Bitcoin USD Price | D36: =($D$4 * $B36) + $D$4 -> 140000 | E36: =(D36 * $B36) + D36 -> 196000 | F36: =(E36 * $B36) + E36 -> 274400 | G36: =(F36 * $B36) + F36 -> 384160 | H36: =(G36 * $B36) + G36 -> 537824 | I36: =(H36 * $B36) + H36 -> 752953.6 | J36: =(I36 * $B36) + I36 -> 1054135 | K36: =(J36 * $B36) + J36 -> 1475789.1 | L36: =(K36 * $B36) + K36 -> 2066104.7 | M36: =(L36 * $B36) + L36 -> 2892546.5
C37: Bitcoin USD Marketcap | D37: =D36*21000000 -> 2940000000000 | E37: =E36*21000000 -> 4116000000000 | F37: =F36*21000000 -> 5762400000000 | G37: =G36*21000000 -> 8067360000000 | H37: =H36*21000000 -> 11294304000000 | I37: =I36*21000000 -> 15812025600000 | J37: =J36*21000000 -> 22136835840000 | K37: =K36*21000000 -> 3.099157e+13 | ... M37: =M36*21000000 -> 6.0743478e+13
C38: Cumulative BTC Yield % | D38: =( ( D36 - $D$4 ) ) / D36 -> 0.28571429 | E38: =( ( E36 - $D$4 ) ) / E36 -> 0.48979592 | F38: =( ( F36 - $D$4 ) ) / F36 -> 0.63556851 | G38: =( ( G36 - $D$4 ) ) / G36 -> 0.7396918 | H38: =( ( H36 - $D$4 ) ) / H36 -> 0.81406557 | I38: =( ( I36 - $D$4 ) ) / I36 -> 0.86718969 | J38: =( ( J36 - $D$4 ) ) / J36 -> 0.90513549 | K38: =( ( K36 - $D$4 ) ) / K36 -> 0.93223964 | ... M38: =( ( M36 - $D$4 ) ) / M36 -> 0.96542839
C39: Remaining BTC Yield % | D39: =1-D38 -> 0.71428571 | E39: =1-E38 -> 0.51020408 | F39: =1-F38 -> 0.36443149 | G39: =1-G38 -> 0.2603082 | H39: =1-H38 -> 0.18593443 | I39: =1-I38 -> 0.13281031 | J39: =1-J38 -> 0.094864506 | K39: =1-K38 -> 0.067760362 | ... M39: =1-M38 -> 0.034571613
C40: Annual BTC Yield % | D40: =D38 -> 0.28571429 | E40: =E38-D38 -> 0.20408163 | F40: =F38-E38 -> 0.14577259 | G40: =G38-F38 -> 0.10412328 | H40: =H38-G38 -> 0.074373773 | I40: =I38-H38 -> 0.053124123 | J40: =J38-I38 -> 0.037945802 | K40: =K38-J38 -> 0.027104145 | L40: =L38-K38 -> 0.019360103 | M40: =M38-L38 -> 0.013828645
C41: Annual Average BTC Yield % | H41: =SUM(D40:H40)/5 -> 0.16281311 | M41: =SUM(D40:M40)/10 -> 0.096542839

Sheet BTC_MORTGAGE
B2: Bitcoin Lightning Mortgage Bitcoin collateral with price drawdown liquidation protection for leveraged Bitcoin growth and Lightning transaction exposure | E2: Test Case | F2: Bitcoin Investor | G2: Fiat Investor | H2: Service Provider | I2: Bitcoin Investor
F3: Stable Provider | G3: Stable Receiver | H3: Stable Receiver | I3: Total Down Payment | J3: Total Debt | K3: High-Interest Debt | L3: Low-Interest Debt | M3: Total Debt-to-Value
B4: Service | C4: Annual ETF Fee | D4: Annual Loan Fee | E4: BTC Total | F4: BTC Principal | G4: BTC Bond/Pref | H4: BTC Loan | I4: BTC Principal % | J4: BTC Debt % | K4: Bond/Pref-to-Value % | L4: Loan-to-Value % | M4: Debt-to-Value %
B5: ="Bitcoin Long " & E5 & "X" -> Bitcoin Long 2X | C5: 0.025 | D5: N/A | E5: 2 | F5: 1 | G5: =F5 -> 1 | H5: =E5-F5-G5 -> 0 | I5: =F5/E5 -> 0.5 | J5: =1-I5 -> 0.5 | K5: =G5/F5 -> 1 | L5: =H5/F5 -> 0 | M5: =K5+L5 -> 1
B6: ="Bitcoin Long " & E6 & "X" -> Bitcoin Long 2.5X | C6: 0.025 | D6: 0.075 | E6: 2.5 | F6: 1 | G6: =F6 -> 1 | H6: =E6-F6-G6 -> 0.5 | I6: =F6/E6 -> 0.4 | J6: =1-I6 -> 0.6 | K6: =G6/F6 -> 1 | L6: =H6/F6 -> 0.5 | M6: =K6+L6 -> 1.5
B7: ="Bitcoin Long " & E7 & "X" -> Bitcoin Long 3X | C7: 0.025 | D7: 0.075 | E7: 3 | F7: 1 | G7: =F7 -> 1 | H7: =E7-F7-G7 -> 1 | I7: =F7/E7 -> 0.33333333 | J7: =1-I7 -> 0.66666667 | K7: =G7/F7 -> 1 | L7: =H7/F7 -> 1 | M7: =K7+L7 -> 2
B8: ="Bitcoin Long " & E8 & "X" -> Bitcoin Long 3.5X | C8: 0.025 | D8: 0.075 | E8: 3.5 | F8: 1 | G8: =F8 -> 1 | H8: =E8-F8-G8 -> 1.5 | I8: =F8/E8 -> 0.28571429 | J8: =1-I8 -> 0.71428571 | K8: =G8/F8 -> 1 | L8: =H8/F8 -> 1.5 | M8: =K8+L8 -> 2.5
B9: ="Bitcoin Long " & E9 & "X" -> Bitcoin Long 4X | C9: 0.025 | D9: 0.075 | E9: 4 | F9: 1 | G9: =F9 -> 1 | H9: =E9-F9-G9 -> 2 | I9: =F9/E9 -> 0.25 | J9: =1-I9 -> 0.75 | K9: =G9/F9 -> 1 | L9: =H9/F9 -> 2 | M9: =K9+L9 -> 3
B10: ="Bitcoin Long " & E10 & "X" -> Bitcoin Long 4.5X | C10: 0.025 | D10: 0.075 | E10: 4.5 | F10: 1 | G10: =F10 -> 1 | H10: =E10-F10-G10 -> 2.5 | I10: =F10/E10 -> 0.22222222 | J10: =1-I10 -> 0.77777778 | K10: =G10/F10 -> 1 | L10: =H10/F10 -> 2.5 | M10: =K10+L10 -> 3.5
B11: ="Bitcoin Long " & E11 & "X" -> Bitcoin Long 5X | C11: 0.025 | D11: 0.075 | E11: 5 | F11: 1 | G11: =F11 -> 1 | H11: =E11-F11-G11 -> 3 | I11: =F11/E11 -> 0.2 | J11: =1-I11 -> 0.8 | K11: =G11/F11 -> 1 | L11: =H11/F11 -> 3 | M11: =K11+L11 -> 4
B12: ="Bitcoin Long " & E12 & "X" -> Bitcoin Long 5.5X | C12: 0.025 | D12: 0.075 | E12: 5.5 | F12: 1 | G12: =F12 -> 1 | H12: =E12-F12-G12 -> 3.5 | I12: =F12/E12 -> 0.18181818 | J12: =1-I12 -> 0.81818182 | K12: =G12/F12 -> 1 | L12: =H12/F12 -> 3.5 | M12: =K12+L12 -> 4.5
B13: ="Bitcoin Long " & E13 & "X" -> Bitcoin Long 6X | C13: 0.025 | D13: 0.075 | E13: 6 | F13: 1 | G13: =F13 -> 1 | H13: =E13-F13-G13 -> 4 | I13: =F13/E13 -> 0.16666667 | J13: =1-I13 -> 0.83333333 | K13: =G13/F13 -> 1 | L13: =H13/F13 -> 4 | M13: =K13+L13 -> 5
B14: ="Bitcoin Long " & E14 & "X" -> Bitcoin Long 6.5X | C14: 0.025 | D14: 0.075 | E14: 6.5 | F14: 1 | G14: =F14 -> 1 | H14: =E14-F14-G14 -> 4.5 | I14: =F14/E14 -> 0.15384615 | J14: =1-I14 -> 0.84615385 | K14: =G14/F14 -> 1 | L14: =H14/F14 -> 4.5 | M14: =K14+L14 -> 5.5
B15: ="Bitcoin Long " & E15 & "X" -> Bitcoin Long 7X | C15: 0.025 | D15: 0.075 | E15: 7 | F15: 1 | G15: =F15 -> 1 | H15: =E15-F15-G15 -> 5 | I15: =F15/E15 -> 0.14285714 | J15: =1-I15 -> 0.85714286 | K15: =G15/F15 -> 1 | L15: =H15/F15 -> 5 | M15: =K15+L15 -> 6
B16: ="Bitcoin Long " & E16 & "X" -> Bitcoin Long 7.5X | C16: 0.025 | D16: 0.075 | E16: 7.5 | F16: 1 | G16: =F16 -> 1 | H16: =E16-F16-G16 -> 5.5 | I16: =F16/E16 -> 0.13333333 | J16: =1-I16 -> 0.86666667 | K16: =G16/F16 -> 1 | L16: =H16/F16 -> 5.5 | M16: =K16+L16 -> 6.5
B17: ="Bitcoin Long " & E17 & "X" -> Bitcoin Long 8X | C17: 0.025 | D17: 0.075 | E17: 8 | F17: 1 | G17: =F17 -> 1 | H17: =E17-F17-G17 -> 6 | I17: =F17/E17 -> 0.125 | J17: =1-I17 -> 0.875 | K17: =G17/F17 -> 1 | L17: =H17/F17 -> 6 | M17: =K17+L17 -> 7
... B41: ="Bitcoin Long " & E41 & "X" -> Bitcoin Long 20X | C41: 0.025 | D41: 0.075 | E41: 20 | F41: 1 | G41: =F41 -> 1 | H41: =E41-F41-G41 -> 18 | I41: =F41/E41 -> 0.05 | J41: =1-I41 -> 0.95 | K41: =G41/F41 -> 1 | L41: =H41/F41 -> 18 | M41: =K41+L41 -> 19

Sheet DC2
C1: Bitcoin Lightning Credit Derivatives
C2: A global, permissionless, decentralized and distributed strategy for ultra-high yields using leveraged Bitcoin growth, liquidity and transaction leasing exposure
C3: Feature | D3: Digital Credit 1.0 | E3: Digital Credit 2.0 | F3: Explainer
C4: Treasury Model | D4: Bitcoin Treasury 1.0, 1.5, 2.0 | E4: Bitcoin Treasury 2.0 | F4: Bitcoin Treasury 2.0 (BT 2.0) is implemented by Bitcoin-native companies with laser focus on bitcoin yield strategies to earn bitcoin revenue instead of through common share dilution.
C5: Capital Provisioning | D5: Centralized and Permissioned | E5: Decentralized and Permissionless | F5: Bitcoiners can permissionlessly provide bitcoin capital to global credit markets and earn true bitcoin yield by participating in the worldwide bitcoin credit market revolution. An example of the power in decentralized and distributed capital means that individuals in the United States can effortlessly provide capital to credit instruments created in Europe.
C6: Capital Risk | D6: Concentrated | E6: Distributed | F6: A distributed approach enables many different bitcoin volatility risk profiles between individuals. Anyone can opt-out providing capital at any time if the bitcoin price underperforms beyond their comfort level however with built-in bitcoin price drawdown liquidation protection only credit obligations are required to maintain the capital position.
C7: Bitcoin Yield Distribution | D7: Concentrated | E7: Distributed | F7: Bitcoin Growth Yield is the Bitcoin Compound Annual Growth Rate from leasing the credit (stable bitcoin) liquidity position. Bitcoin Liquidity Yield is the Lightning fees obtained from leasing the credit (stable bitcoin) and capital (volatile bitcoin) liquidity positions. Bitcoin Transaction Yield is the Lightning fees obtained from routing fees in the credit (stable bitcoin) and capital (volatile bitcoin) liquidity positions Capital Providers receive 100% of the Bitcoin Yield with fiat-denominated fees deducted thus eliminating the need to dilute common shareholders.
B8: Credit Obligation Funding Strategy | D8: Common Shareholders | E8: Capital Providers
C9: Service Revenue | D9: None | E9: Bitcoin-Denominated Service Fees
C10: Service Infrastructure | D10: Traditional Finance | E10: Streaming Finance using the Bitcoin Lightning Network | F10: While there remains a small overhead of credit-based products built using Traditional Finance such as bonds, preferred shares, and loans the majority of the effort is bitcoinizing those Real World Liabilities (RWL) using bitcoin-backed products and services on the Lightning Network with Lightning Stable Channels as a mechanism to balance bitcoin stable to fiat with bitcoin volatile using leverage.
B11: Bitcoin Total Value Locked Growth Rate | D11: 1X = 1 BTC buy adds 1 BTC to TVL | E11: 2X = 1 BTC buy adds 2 BTC to TVL 3X = 1 BTC buy adds 1.5 BTC to TVL | F11: Bitcoin TVL is increased at a faster rate due to the decentralized capital participation model. A BTC & LN Long 2X position commands a double growth rate increase to the purchased bitcoin while a BTC & LN Long 3X position commands a 50% growth rate increase to the purchased bitcoin due to the reduction of capital.

Sheet SUMMARY
B2: Bitcoin Lightning Credit Derivatives | R2: X: @KyleHutch_
B3: A global, permissionless, decentralized and distributed strategy for ultra-high yields using leveraged Bitcoin growth, liquidity and transaction leasing exposure | R3: 46071
B5: A M P L I F Y Y O U R B I T C O I N | C5: O N T H E L I G H T N I N G N E T W O R K | F5: A N N U A L I Z E D B I T C O I N Y I E L D | H5: F I A T G R O W T H | L5: B T C L I Q U I D I T Y | P5: B T C T R A N S A C T I O N
H6: 0.29 | L6: 0.02 | P6: 0.01
B8: C A P I T A L L E V E R A G E | F8: 2 X | H8: 2 . 5 X | J8: 3 X | L8: 3 . 5 X | N8: 4 X | P8: 4 . 5 X | R8: 5 X
B9: L E A S E T O C A P I T A L | D9: S E C U R I T Y | F9: 1 | H9: 1 | J9: 1 | L9: 1 | N9: 1 | P9: 1 | R9: 1
D10: D E B T | F10: 0 | H10: 0.5 | J10: 1 | L10: 1.5 | N10: 2 | P10: 2.5 | R10: 3
B11: B I T C O I N L E A S I N G Y I E L D A N N U A L I Z E D B T C 5 Y E A R A V E R A G E | D11: G R O W T H | F11: ='2X'!I24 -> 0.14401374 | H11: ='2.5X'!I24 -> 0.21602061 | J11: ='3X'!I24 -> 0.28802748 | L11: ='3.5X'!I24 -> 0.36003435 | N11: ='4X'!I24 -> 0.43204122 | P11: ='4.5X'!I24 -> 0.5040481 | R11: ='5X'!I24 -> 0.57605497
D12: L I Q U I D I T Y | F12: ='2X'!I26 -> 0.029931982 | H12: ='2.5X'!I26 -> 0.039931982 | J12: ='3X'!I26 -> 0.049931982 | L12: ='3.5X'!I26 -> 0.059931982 | N12: ='4X'!I26 -> 0.069931982 | P12: ='4.5X'!I26 -> 0.079931982 | R12: ='5X'!I26 -> 0.089931982
D13: T R A N S A C T I O N | F13: ='2X'!I29 -> 0.014965991 | H13: ='2.5X'!I29 -> 0.019965991 | J13: ='3X'!I29 -> 0.024965991 | L13: ='3.5X'!I29 -> 0.029965991 | N13: ='4X'!I29 -> 0.034965991 | P13: ='4.5X'!I29 -> 0.039965991 | R13: ='5X'!I29 -> 0.044965991
D14: G R O S S T O T A L | F14: =SUM(F11:F13) -> 0.18891171 | H14: =SUM(H11:H13) -> 0.27591859 | J14: =SUM(J11:J13) -> 0.36292546 | L14: =SUM(L11:L13) -> 0.44993233 | N14: =SUM(N11:N13) -> 0.5369392 | P14: =SUM(P11:P13) -> 0.62394607 | R14: =SUM(R11:R13) -> 0.71095294
D15: N E T T O T A L | F15: ='2X'!I110 -> 0.11442185 | H15: ='2.5X'!I110 -> 0.18280625 | J15: ='3X'!I110 -> 0.25119066 | L15: ='3.5X'!I110 -> 0.31957506 | N15: ='4X'!I110 -> 0.38795947 | P15: ='4.5X'!I110 -> 0.45634387 | R15: ='5X'!I110 -> 0.52472827
B16: B I T C O I N L E A S I N G Y I E L D A N N U A L I Z E D B T C 10 Y E A R A V E R A G E | D16: G R O W T H | F16: ='2X'!N24 -> 0.092163847 | H16: ='2.5X'!N24 -> 0.13824577 | J16: ='3X'!N24 -> 0.18432769 | L16: ='3.5X'!N24 -> 0.23040962 | N16: ='4X'!N24 -> 0.27649154 | P16: ='4.5X'!N24 -> 0.32257347 | R16: ='5X'!N24 -> 0.36865539
D17: L I Q U I D I T Y | F17: ='2X'!N26 -> 0.026356127 | H17: ='2.5X'!N26 -> 0.036356127 | J17: ='3X'!N26 -> 0.046356127 | L17: ='3.5X'!N26 -> 0.056356127 | N17: ='4X'!N26 -> 0.066356127 | P17: ='4.5X'!N26 -> 0.076356127 | R17: ='5X'!N26 -> 0.086356127
D18: T R A N S A C T I O N | F18: ='2X'!N29 -> 0.013178064 | H18: ='2.5X'!N29 -> 0.018178064 | J18: ='3X'!N29 -> 0.023178064 | L18: ='3.5X'!N29 -> 0.028178064 | N18: ='4X'!N29 -> 0.033178064 | P18: ='4.5X'!N29 -> 0.038178064 | R18: ='5X'!N29 -> 0.043178064
D19: G R O S S T O T A L | F19: =SUM(F16:F18) -> 0.13169804 | H19: =SUM(H16:H18) -> 0.19277996 | J19: =SUM(J16:J18) -> 0.25386189 | L19: =SUM(L16:L18) -> 0.31494381 | N19: =SUM(N16:N18) -> 0.37602573 | P19: =SUM(P16:P18) -> 0.43710766 | R19: =SUM(R16:R18) -> 0.49818958
D20: N E T T O T A L | F20: ='2X'!N110 -> 0.084027083 | H20: ='2.5X'!N110 -> 0.13319127 | J20: ='3X'!N110 -> 0.18235545 | L20: ='3.5X'!N110 -> 0.23151964 | N20: ='4X'!N110 -> 0.28068382 | P20: ='4.5X'!N110 -> 0.32984801 | R20: ='5X'!N110 -> 0.37901219
B21: B I T C O I N L E A S I N G F E E S A N N U A L I Z E D F I A T | D21: S E C U R I T Y | F21: 0.1 | H21: 0.1 | J21: 0.1 | L21: 0.1 | N21: 0.1 | P21: 0.1 | R21: 0.1
D22: S E R V I C E | F22: 0.05 | H22: 0.05 | J22: 0.05 | L22: 0.05 | N22: 0.05 | P22: 0.05 | R22: 0.05
D23: D E B T | F23: 0 | H23: 0.075 | J23: 0.075 | L23: 0.075 | N23: 0.075 | P23: 0.075 | R23: 0.075

Sheet 2X
B2: Bitcoin Lightning Credit Derivatives A permissionless, decentralized and distributed strategy for ultra-high yields using leveraged bitcoin growth and lightning transaction fee exposure | D2: Bitcoin Yield Estimate Variables BiGY = Bitcoin Growth Yield (CAGR) BiLY = Bitcoin Liquidity Yield BiTY = Bitcoin Transaction Yield | G2: Bitcoin Yield Estimate 5 Year Summary SR = Stable Receiver SB = Stable Balancer SP = Stable Provider | K2: Lightning Bank 5 Year Revenue Summary TVL = Total Value Locked
K3: Bitcoin TVL | L3: Measure | M3: BTC | N3: USD
D4: Bitcoin USD Price Start | E4: 100000 | G4: SR USD Comp. | H4: Annual Avg. % | I4: =I43 -> 0.17740036 | K4: =C127 -> 20000 | L4: Annual Avg. | M4: =I128 -> 248.29955 | N4: =M4*$I$15 -> 88700178
D5: Annual Bitcoin Growth Yield % | E5: =SUMMARY!H6 -> 0.29 | G5: SP BiGY BTC | H5: Annual Avg. % | I5: =I67 -> 0.14401374 | K5: =C127 -> 20000 | L5: Cumulative | M5: =I129 -> 1241.4978 | N5: =M5*$I$15 -> 4.4350089e+08
D6: Annual Bitcoin Liquidity Yield % | E6: =SUMMARY!L6 -> 0.02 | G6: SP BiLY BTC | H6: Annual Avg. % | I6: =I80 -> 0.029931982 | K6: =C130 -> 400000 | L6: Annual Avg. | M6: =I131 -> 4965.9911 | N6: =M6*$I$15 -> 1.7740036e+09
D7: Annual Bitcoin Transaction Yield % | E7: =SUMMARY!P6 -> 0.01 | G7: SP BiTY BTC | H7: Annual Avg. % | I7: =I95 -> 0.014965991 | K7: =C130 -> 400000 | L7: Cumulative | M7: =I132 -> 24829.955 | N7: =M7*$I$15 -> 8.8700178e+09
D8: Stable Receiver Security Annual USD % | E8: =SUMMARY!F21 -> 0.1 | G8: SP BiLY SR BTC | H8: Annual Avg. % | I8: =-I35 -> -0.049659911 | K8: =C133 -> 1000000 | L8: Annual Avg. | M8: =I134 -> 12414.978 | N8: =M8*$I$15 -> 4435008905
D9: Stable Balancer Security Annual USD % | E9: =SUMMARY!F22 -> 0.05 | G9: SP BiLY SB BTC | H9: Annual Avg. % | I9: =-I51 -> -0.024829955 | K9: =C133 -> 1000000 | L9: Cumulative | M9: =I135 -> 62074.889 | N9: =M9*$I$15 -> 2.2175045e+10
D10: Stable Balancer Debt Annual USD % | E10: =SUMMARY!F23 -> 0 | G10: SP Total BTC | H10: Annual Avg. % | I10: =I110 -> 0.11442185
D11: Stable Provider Debt-to-Value % | E11: =SUMMARY!F10 -> 0
B13: Yield Estimate Calculator | C13: Unit of Account | D13: Measure | E13: Year 1 | F13: Year 2 | G13: Year 3 | H13: Year 4 | I13: Year 5 | J13: Year 6 | K13: Year 7 | L13: Year 8 | M13: Year 9 | N13: Year 10
B15: Bitcoin | C15: USD | D15: Price | E15: =($E$4 * $E$5) + $E$4 -> 129000 | F15: =(E15 * $E$5) + E15 -> 166410 | G15: =(F15 * $E$5) + F15 -> 214668.9 | H15: =(G15 * $E$5) + G15 -> 276922.88 | I15: =(H15 * $E$5) + H15 -> 357230.52 | J15: =(I15 * $E$5) + I15 -> 460827.37 | K15: =(J15 * $E$5) + J15 -> 594467.3 | L15: =(K15 * $E$5) + K15 -> 766862.82 | M15: =(L15 * $E$5) + L15 -> 989253.04 | N15: =(M15 * $E$5) + M15 -> 1276136.4
D16: Marketcap | E16: =E15*21000000 -> 2709000000000 | F16: =F15*21000000 -> 3494610000000 | G16: =G15*21000000 -> 4508046900000 | H16: =H15*21000000 -> 5815380501000 | I16: =I15*21000000 -> 7.5018408e+12 | J16: =J15*21000000 -> 9.6773747e+12 | K16: =K15*21000000 -> 1.2483813e+13 | L16: =L15*21000000 -> 1.6104119e+13 | ... N16: =N15*21000000 -> 2.6798865e+13
B17: Bitcoin Growth Yield (BiGY) | C17: BTC | D17: Stable Security Cumulative % | E17: =(E15-$E4)/E15 -> 0.2248062 | F17: =(F15-$E4)/F15 -> 0.39907457 | G17: =(G15-$E4)/G15 -> 0.53416634 | H17: =(H15-$E4)/H15 -> 0.63888863 | I17: =(I15-$E4)/I15 -> 0.72006871 | J17: =(J15-$E4)/J15 -> 0.782999 | K17: =(K15-$E4)/K15 -> 0.83178217 | L17: =(L15-$E4)/L15 -> 0.86959858 | ... N17: =(N15-$E4)/N15 -> 0.92163847
D18: Stable Security Remaining % | E18: =1-E17 -> 0.7751938 | F18: =1-F17 -> 0.60092543 | G18: =1-G17 -> 0.46583366 | H18: =1-H17 -> 0.36111137 | I18: =1-I17 -> 0.27993129 | J18: =1-J17 -> 0.217001 | K18: =1-K17 -> 0.16821783 | L18: =1-L17 -> 0.13040142 | ... N18: =1-N17 -> 0.078361528
D19: Stable Security Annual % | E19: =E17 -> 0.2248062 | F19: =F17-E17 -> 0.17426837 | G19: =G17-F17 -> 0.13509176 | H19: =H17-G17 -> 0.1047223 | I19: =I17-H17 -> 0.081180075 | J19: =J17-I17 -> 0.06293029 | K19: =K17-J17 -> 0.048783171 | L19: =L17-K17 -> 0.037816412 | M19: =M17-L17 -> 0.029315048 | N19: =N17-M17 -> 0.022724843
D20: Stable Security Annual Average % | I20: =AVERAGE(E19:I19) -> 0.14401374 | N20: =AVERAGE(E19:N19) -> 0.092163847
D21: Stable Debt Annual % | E21: =$E$11*E19 -> 0 | F21: =$E$11*F19 -> 0 | G21: =$E$11*G19 -> 0 | H21: =$E$11*H19 -> 0 | I21: =$E$11*I19 -> 0 | J21: =$E$11*J19 -> 0 | K21: =$E$11*K19 -> 0 | L21: =$E$11*L19 -> 0 | ... N21: =$E$11*N19 -> 0
D22: Stable Debt Annual Avg. % | I22: =AVERAGE(E21:I21) -> 0 | N22: =AVERAGE(E21:N21) -> 0
D23: Total Annual % | E23: =E19+E21 -> 0.2248062 | F23: =F19+F21 -> 0.17426837 | G23: =G19+G21 -> 0.13509176 | H23: =H19+H21 -> 0.1047223 | I23: =I19+I21 -> 0.081180075 | J23: =J19+J21 -> 0.06293029 | K23: =K19+K21 -> 0.048783171 | L23: =L19+L21 -> 0.037816412 | ... N23: =N19+N21 -> 0.022724843
D24: Total Annual Average % | I24: =AVERAGE(E23:I23) -> 0.14401374 | N24: =AVERAGE(E23:N23) -> 0.092163847
B25: Bitcoin Liquidity Yield (BiLY) | C25: BTC | D25: Annual % | E25: =((1+$E$11)*$E$6)+($E$6*E18) -> 0.035503876 | F25: =((1+$E$11)*$E$6)+($E$6*F18) -> 0.032018509 | G25: =((1+$E$11)*$E$6)+($E$6*G18) -> 0.029316673 | H25: =((1+$E$11)*$E$6)+($E$6*H18) -> 0.027222227 | I25: =((1+$E$11)*$E$6)+($E$6*I18) -> 0.025598626 | J25: =((1+$E$11)*$E$6)+($E$6*J18) -> 0.02434002 | K25: =((1+$E$11)*$E$6)+($E$6*K18) -> 0.023364357 | L25: =((1+$E$11)*$E$6)+($E$6*L18) -> 0.022608028 | ... N25: =((1+$E$11)*$E$6)+($E$6*N18) -> 0.021567231
D26: Annual Average % | I26: =AVERAGE(E25:I25) -> 0.029931982 | N26: =AVERAGE(E25:N25) -> 0.026356127
D27: Cumulative % | E27: =E25 -> 0.035503876 | F27: =E27+F25 -> 0.067522384 | G27: =F27+G25 -> 0.096839058 | H27: =G27+H25 -> 0.12406129 | I27: =H27+I25 -> 0.14965991 | J27: =I27+J25 -> 0.17399993 | K27: =J27+K25 -> 0.19736429 | L27: =K27+L25 -> 0.21997232 | M27: =L27+M25 -> 0.24199404 | N27: =M27+N25 -> 0.26356127
B28: Bitcoin Transaction Yield (BiTY) | C28: BTC | D28: Annual % | E28: =((1+$E$11)*$E$7)+($E$7*E18) -> 0.017751938 | F28: =((1+$E$11)*$E$7)+($E$7*F18) -> 0.016009254 | G28: =((1+$E$11)*$E$7)+($E$7*G18) -> 0.014658337 | H28: =((1+$E$11)*$E$7)+($E$7*H18) -> 0.013611114 | I28: =((1+$E$11)*$E$7)+($E$7*I18) -> 0.012799313 | J28: =((1+$E$11)*$E$7)+($E$7*J18) -> 0.01217001 | K28: =((1+$E$11)*$E$7)+($E$7*K18) -> 0.011682178 | L28: =((1+$E$11)*$E$7)+($E$7*L18) -> 0.011304014 | ... N28: =((1+$E$11)*$E$7)+($E$7*N18) -> 0.010783615
D29: Annual Average % | I29: =AVERAGE(E28:I28) -> 0.014965991 | N29: =AVERAGE(E28:N28) -> 0.013178064
D30: Cumulative % | E30: =E28 -> 0.017751938 | F30: =E30+F28 -> 0.033761192 | G30: =F30+G28 -> 0.048419529 | H30: =G30+H28 -> 0.062030643 | I30: =H30+I28 -> 0.074829955 | J30: =I30+J28 -> 0.086999965 | K30: =J30+K28 -> 0.098682144 | L30: =K30+L28 -> 0.10998616 | M30: =L30+M28 -> 0.12099702 | N30: =M30+N28 -> 0.13178064
B32: Stable Receiver / Fiat Lender | C32: Test Case | D32: ="10 BTC / "&TEXT($E$4*10, "$###0.00,,")&"M USD" -> 10 BTC / $1.00M USD | E32: Year 1 | F32: Year 2 | G32: Year 3 | H32: Year 4 | I32: Year 5 | J32: Year 6 | K32: Year 7 | L32: Year 8 | M32: Year 9 | N32: Year 10
B34: Bitcoin Liquidity Yield (BiLY) | C34: BTC | D34: Total Annual % | E34: =E39*$E$4/E$15 -> 0.07751938 | F34: =F39*$E$4/F$15 -> 0.060092543 | G34: =G39*$E$4/G$15 -> 0.046583366 | H34: =H39*$E$4/H$15 -> 0.036111137 | I34: =I39*$E$4/I$15 -> 0.027993129 | J34: =J39*$E$4/J$15 -> 0.0217001 | K34: =K39*$E$4/K$15 -> 0.016821783 | L34: =L39*$E$4/L$15 -> 0.013040142 | ... N34: =N39*$E$4/N$15 -> 0.0078361528
D35: Total Annual Average % | I35: =AVERAGE(E34:I34) -> 0.049659911 | N35: =AVERAGE(E34:N34) -> 0.031780637
D36: Cumulative % | E36: =E$17*(E34/E$19) -> 0.07751938 | F36: =F$17*(F34/F$19) -> 0.13761192 | G36: =G$17*(G34/G$19) -> 0.18419529 | H36: =H$17*(H34/H$19) -> 0.22030643 | I36: =I$17*(I34/I$19) -> 0.24829955 | J36: =J$17*(J34/J$19) -> 0.26999965 | K36: =K$17*(K34/K$19) -> 0.28682144 | L36: =L$17*(L34/L$19) -> 0.29986158 | ... N36: =N$17*(N34/N$19) -> 0.31780637
D37: Test Case Annual | E37: =10*E34 -> 0.7751938 | F37: =10*F34 -> 0.60092543 | G37: =10*G34 -> 0.46583366 | H37: =10*H34 -> 0.36111137 | I37: =10*I34 -> 0.27993129 | J37: =10*J34 -> 0.217001 | K37: =10*K34 -> 0.16821783 | L37: =10*L34 -> 0.13040142 | ... N37: =10*N34 -> 0.078361528
D38: Test Case Cumulative | E38: =10*E36 -> 0.7751938 | F38: =10*F36 -> 1.3761192 | G38: =10*G36 -> 1.8419529 | H38: =10*H36 -> 2.2030643 | I38: =10*I36 -> 2.4829955 | J38: =10*J36 -> 2.6999965 | K38: =10*K36 -> 2.8682144 | L38: =10*L36 -> 2.9986158 | ... N38: =10*N36 -> 3.1780637
C39: USD Simple | D39: Annual % | E39: =E8 -> 0.1 | F39: =E39 -> 0.1 | G39: =F39 -> 0.1 | H39: =G39 -> 0.1 | I39: =H39 -> 0.1 | J39: =I39 -> 0.1 | K39: =J39 -> 0.1 | L39: =K39 -> 0.1 | M39: =L39 -> 0.1 | N39: =M39 -> 0.1
D40: Test Case Annual | E40: =E37*E$15 -> 100000 | F40: =F37*F$15 -> 100000 | G40: =G37*G$15 -> 100000 | H40: =H37*H$15 -> 100000 | I40: =I37*I$15 -> 100000 | J40: =J37*J$15 -> 100000 | K40: =K37*K$15 -> 100000 | L40: =L37*L$15 -> 100000 | ... N40: =N37*N$15 -> 100000
D41: Test Case Cumulative | E41: =E40 -> 100000 | F41: =E41+F40 -> 200000 | G41: =F41+G40 -> 300000 | H41: =G41+H40 -> 400000 | I41: =H41+I40 -> 500000 | J41: =I41+J40 -> 600000 | K41: =J41+K40 -> 700000 | L41: =K41+L40 -> 800000 | M41: =L41+M40 -> 900000 | N41: =M41+N40 -> 1000000
C42: USD Compounded | D42: Annual % | E42: =E36*E$15/$E$4 -> 0.1 | F42: =F36*F$15/$E$4-E42 -> 0.129 | G42: =G36*G$15/$E$4-F42-E42 -> 0.16641 | H42: =H36*H$15/$E$4-G42-F42-E42 -> 0.2146689 | I42: =I36*I$15/$E$4-H42-G42-F42-E42 -> 0.27692288 | J42: =J36*J$15/$E$4-I42-H42-G42-F42-E42 -> 0.35723052 | K42: =K36*K$15/$E$4-J42-I42-H42-G42-F42-E42 -> 0.46082737 | L42: =L36*L$15/$E$4-K42-J42-I42-H42-G42-F42-E42 -> 0.5944673 | M42: =M36*M$15/$E$4-L42-K42-J42-I42-H42-G42-F42-E42 -> 0.76686282 | N42: =N36*N$15/$E$4-M42-L42-K42-J42-I42-H42-G42-F42-E42 -> 0.98925304
D43: Annual Average % | I43: =AVERAGE(E42:I42) -> 0.17740036 | N43: =AVERAGE(E42:N42) -> 0.40556428
D44: Test Case Annual | E44: =E46 -> 100000 | F44: =F46-E46 -> 129000 | G44: =G46-F46 -> 166410 | H44: =H46-G46 -> 214668.9 | I44: =I46-H46 -> 276922.88 | J44: =J46-I46 -> 357230.52 | K44: =K46-J46 -> 460827.37 | L44: =L46-K46 -> 594467.3 | M44: =M46-L46 -> 766862.82 | N44: =N46-M46 -> 989253.04
D45: Test Case Annual Average | I45: =AVERAGE(E44:I44) -> 177400.36 | N45: =AVERAGE(E44:N44) -> 405564.28
...

Sheet 2.5X
B2: Bitcoin Lightning Credit Derivatives A permissionless, decentralized and distributed strategy for ultra-high yields using leveraged bitcoin growth and lightning transaction fee exposure | D2: Bitcoin Yield Estimate Variables BiGY = Bitcoin Growth Yield (CAGR) BiLY = Bitcoin Liquidity Yield BiTY = Bitcoin Transaction Yield | G2: Bitcoin Yield Estimate 5 Year Summary SR = Stable Receiver SB = Stable Balancer SP = Stable Provider | K2: Lightning Bank 5 Year Revenue Summary TVL = Total Value Locked
K3: Bitcoin TVL | L3: Measure | M3: BTC | N3: USD
D4: Bitcoin USD Price Start | E4: 100000 | G4: SR USD Comp. | H4: Annual Avg. % | I4: =I43 -> 0.17740036 | K4: =C127 -> 20000 | L4: Annual Avg. | M4: =I128 -> 347.61938 | N4: =M4*$I$15 -> 1.2418025e+08
D5: Annual Bitcoin Growth Yield % | E5: =SUMMARY!H6 -> 0.29 | G5: SP BiGY BTC | H5: Annual Avg. % | I5: =I67 -> 0.21602061 | K5: =C127 -> 20000 | L5: Cumulative | M5: =I129 -> 1738.0969 | N5: =M5*$I$15 -> 6.2090125e+08
D6: Annual Bitcoin Liquidity Yield % | E6: =SUMMARY!L6 -> 0.02 | G6: SP BiLY BTC | H6: Annual Avg. % | I6: =I80 -> 0.039931982 | K6: =C130 -> 400000 | L6: Annual Avg. | M6: =I131 -> 6952.3875 | N6: =M6*$I$15 -> 2.483605e+09
D7: Annual Bitcoin Transaction Yield % | E7: =SUMMARY!P6 -> 0.01 | G7: SP BiTY BTC | H7: Annual Avg. % | I7: =I95 -> 0.019965991 | K7: =C130 -> 400000 | L7: Cumulative | M7: =I132 -> 34761.938 | N7: =M7*$I$15 -> 1.2418025e+10
D8: Stable Receiver Security Annual USD % | E8: =SUMMARY!H21 -> 0.1 | G8: SP BiLY SR BTC | H8: Annual Avg. % | I8: =-I35 -> -0.049659911 | K8: =C133 -> 1000000 | L8: Annual Avg. | M8: =I134 -> 17380.969 | N8: =M8*$I$15 -> 6209012467
D9: Stable Balancer Security Annual USD % | E9: =SUMMARY!H22 -> 0.05 | G9: SP BiLY SB BTC | H9: Annual Avg. % | I9: =-I51 -> -0.043452422 | K9: =C133 -> 1000000 | L9: Cumulative | M9: =I135 -> 86904.844 | N9: =M9*$I$15 -> 3.1045062e+10
D10: Stable Balancer Debt Annual USD % | E10: =SUMMARY!H23 -> 0.075 | G10: SP Total BTC | H10: Annual Avg. % | I10: =I110 -> 0.18280625
D11: Stable Provider Debt-to-Value % | E11: =SUMMARY!H10 -> 0.5
B13: Yield Estimate Calculator | C13: Unit of Account | D13: Measure | E13: Year 1 | F13: Year 2 | G13: Year 3 | H13: Year 4 | I13: Year 5 | J13: Year 6 | K13: Year 7 | L13: Year 8 | M13: Year 9 | N13: Year 10
B15: Bitcoin | C15: USD | D15: Price | E15: =($E$4 * $E$5) + $E$4 -> 129000 | F15: =(E15 * $E$5) + E15 -> 166410 | G15: =(F15 * $E$5) + F15 -> 214668.9 | H15: =(G15 * $E$5) + G15 -> 276922.88 | I15: =(H15 * $E$5) + H15 -> 357230.52 | J15: =(I15 * $E$5) + I15 -> 460827.37 | K15: =(J15 * $E$5) + J15 -> 594467.3 | L15: =(K15 * $E$5) + K15 -> 766862.82 | M15: =(L15 * $E$5) + L15 -> 989253.04 | N15: =(M15 * $E$5) + M15 -> 1276136.4
D16: Marketcap | E16: =E15*21000000 -> 2709000000000 | F16: =F15*21000000 -> 3494610000000 | G16: =G15*21000000 -> 4508046900000 | H16: =H15*21000000 -> 5815380501000 | I16: =I15*21000000 -> 7.5018408e+12 | J16: =J15*21000000 -> 9.6773747e+12 | K16: =K15*21000000 -> 1.2483813e+13 | L16: =L15*21000000 -> 1.6104119e+13 | ... N16: =N15*21000000 -> 2.6798865e+13
B17: Bitcoin Growth Yield (BiGY) | C17: BTC | D17: Stable Security Cumulative % | E17: =(E15-$E4)/E15 -> 0.2248062 | F17: =(F15-$E4)/F15 -> 0.39907457 | G17: =(G15-$E4)/G15 -> 0.53416634 | H17: =(H15-$E4)/H15 -> 0.63888863 | I17: =(I15-$E4)/I15 -> 0.72006871 | J17: =(J15-$E4)/J15 -> 0.782999 | K17: =(K15-$E4)/K15 -> 0.83178217 | L17: =(L15-$E4)/L15 -> 0.86959858 | ... N17: =(N15-$E4)/N15 -> 0.92163847
D18: Stable Security Remaining % | E18: =1-E17 -> 0.7751938 | F18: =1-F17 -> 0.60092543 | G18: =1-G17 -> 0.46583366 | H18: =1-H17 -> 0.36111137 | I18: =1-I17 -> 0.27993129 | J18: =1-J17 -> 0.217001 | K18: =1-K17 -> 0.16821783 | L18: =1-L17 -> 0.13040142 | ... N18: =1-N17 -> 0.078361528
D19: Stable Security Annual % | E19: =E17 -> 0.2248062 | F19: =F17-E17 -> 0.17426837 | G19: =G17-F17 -> 0.13509176 | H19: =H17-G17 -> 0.1047223 | I19: =I17-H17 -> 0.081180075 | J19: =J17-I17 -> 0.06293029 | K19: =K17-J17 -> 0.048783171 | L19: =L17-K17 -> 0.037816412 | M19: =M17-L17 -> 0.029315048 | N19: =N17-M17 -> 0.022724843
D20: Stable Security Annual Average % | I20: =AVERAGE(E19:I19) -> 0.14401374 | N20: =AVERAGE(E19:N19) -> 0.092163847
D21: Stable Debt Annual % | E21: =$E$11*E19 -> 0.1124031 | F21: =$E$11*F19 -> 0.087134187 | G21: =$E$11*G19 -> 0.067545881 | H21: =$E$11*H19 -> 0.052361148 | I21: =$E$11*I19 -> 0.040590037 | J21: =$E$11*J19 -> 0.031465145 | K21: =$E$11*K19 -> 0.024391585 | L21: =$E$11*L19 -> 0.018908206 | ... N21: =$E$11*N19 -> 0.011362422
D22: Stable Debt Annual Avg. % | I22: =AVERAGE(E21:I21) -> 0.072006871 | N22: =AVERAGE(E21:N21) -> 0.046081924
D23: Total Annual % | E23: =E19+E21 -> 0.3372093 | F23: =F19+F21 -> 0.26140256 | G23: =G19+G21 -> 0.20263764 | H23: =H19+H21 -> 0.15708344 | I23: =I19+I21 -> 0.12177011 | J23: =J19+J21 -> 0.094395436 | K23: =K19+K21 -> 0.073174756 | L23: =L19+L21 -> 0.056724617 | ... N23: =N19+N21 -> 0.034087265
D24: Total Annual Average % | I24: =AVERAGE(E23:I23) -> 0.21602061 | N24: =AVERAGE(E23:N23) -> 0.13824577
B25: Bitcoin Liquidity Yield (BiLY) | C25: BTC | D25: Annual % | E25: =((1+$E$11)*$E$6)+($E$6*E18) -> 0.045503876 | F25: =((1+$E$11)*$E$6)+($E$6*F18) -> 0.042018509 | G25: =((1+$E$11)*$E$6)+($E$6*G18) -> 0.039316673 | H25: =((1+$E$11)*$E$6)+($E$6*H18) -> 0.037222227 | I25: =((1+$E$11)*$E$6)+($E$6*I18) -> 0.035598626 | J25: =((1+$E$11)*$E$6)+($E$6*J18) -> 0.03434002 | K25: =((1+$E$11)*$E$6)+($E$6*K18) -> 0.033364357 | L25: =((1+$E$11)*$E$6)+($E$6*L18) -> 0.032608028 | ... N25: =((1+$E$11)*$E$6)+($E$6*N18) -> 0.031567231
D26: Annual Average % | I26: =AVERAGE(E25:I25) -> 0.039931982 | N26: =AVERAGE(E25:N25) -> 0.036356127
D27: Cumulative % | E27: =E25 -> 0.045503876 | F27: =E27+F25 -> 0.087522384 | G27: =F27+G25 -> 0.12683906 | H27: =G27+H25 -> 0.16406129 | I27: =H27+I25 -> 0.19965991 | J27: =I27+J25 -> 0.23399993 | K27: =J27+K25 -> 0.26736429 | L27: =K27+L25 -> 0.29997232 | M27: =L27+M25 -> 0.33199404 | N27: =M27+N25 -> 0.36356127
B28: Bitcoin Transaction Yield (BiTY) | C28: BTC | D28: Annual % | E28: =((1+$E$11)*$E$7)+($E$7*E18) -> 0.022751938 | F28: =((1+$E$11)*$E$7)+($E$7*F18) -> 0.021009254 | G28: =((1+$E$11)*$E$7)+($E$7*G18) -> 0.019658337 | H28: =((1+$E$11)*$E$7)+($E$7*H18) -> 0.018611114 | I28: =((1+$E$11)*$E$7)+($E$7*I18) -> 0.017799313 | J28: =((1+$E$11)*$E$7)+($E$7*J18) -> 0.01717001 | K28: =((1+$E$11)*$E$7)+($E$7*K18) -> 0.016682178 | L28: =((1+$E$11)*$E$7)+($E$7*L18) -> 0.016304014 | ... N28: =((1+$E$11)*$E$7)+($E$7*N18) -> 0.015783615
D29: Annual Average % | I29: =AVERAGE(E28:I28) -> 0.019965991 | N29: =AVERAGE(E28:N28) -> 0.018178064
D30: Cumulative % | E30: =E28 -> 0.022751938 | F30: =E30+F28 -> 0.043761192 | G30: =F30+G28 -> 0.063419529 | H30: =G30+H28 -> 0.082030643 | I30: =H30+I28 -> 0.099829955 | J30: =I30+J28 -> 0.11699997 | K30: =J30+K28 -> 0.13368214 | L30: =K30+L28 -> 0.14998616 | M30: =L30+M28 -> 0.16599702 | N30: =M30+N28 -> 0.18178064
B32: Stable Receiver / Fiat Lender | C32: Test Case | D32: ="10 BTC / "&TEXT($E$4*10, "$###0.00,,")&"M USD" -> 10 BTC / $1.00M USD | E32: Year 1 | F32: Year 2 | G32: Year 3 | H32: Year 4 | I32: Year 5 | J32: Year 6 | K32: Year 7 | L32: Year 8 | M32: Year 9 | N32: Year 10
B34: Bitcoin Liquidity Yield (BiLY) | C34: BTC | D34: Total Annual % | E34: =E39*$E$4/E$15 -> 0.07751938 | F34: =F39*$E$4/F$15 -> 0.060092543 | G34: =G39*$E$4/G$15 -> 0.046583366 | H34: =H39*$E$4/H$15 -> 0.036111137 | I34: =I39*$E$4/I$15 -> 0.027993129 | J34: =J39*$E$4/J$15 -> 0.0217001 | K34: =K39*$E$4/K$15 -> 0.016821783 | L34: =L39*$E$4/L$15 -> 0.013040142 | ... N34: =N39*$E$4/N$15 -> 0.0078361528
D35: Total Annual Average % | I35: =AVERAGE(E34:I34) -> 0.049659911 | N35: =AVERAGE(E34:N34) -> 0.031780637
D36: Cumulative % | E36: =E$17*(E34/E$19) -> 0.07751938 | F36: =F$17*(F34/F$19) -> 0.13761192 | G36: =G$17*(G34/G$19) -> 0.18419529 | H36: =H$17*(H34/H$19) -> 0.22030643 | I36: =I$17*(I34/I$19) -> 0.24829955 | J36: =J$17*(J34/J$19) -> 0.26999965 | K36: =K$17*(K34/K$19) -> 0.28682144 | L36: =L$17*(L34/L$19) -> 0.29986158 | ... N36: =N$17*(N34/N$19) -> 0.31780637
D37: Test Case Annual | E37: =10*E34 -> 0.7751938 | F37: =10*F34 -> 0.60092543 | G37: =10*G34 -> 0.46583366 | H37: =10*H34 -> 0.36111137 | I37: =10*I34 -> 0.27993129 | J37: =10*J34 -> 0.217001 | K37: =10*K34 -> 0.16821783 | L37: =10*L34 -> 0.13040142 | ... N37: =10*N34 -> 0.078361528
D38: Test Case Cumulative | E38: =10*E36 -> 0.7751938 | F38: =10*F36 -> 1.3761192 | G38: =10*G36 -> 1.8419529 | H38: =10*H36 -> 2.2030643 | I38: =10*I36 -> 2.4829955 | J38: =10*J36 -> 2.6999965 | K38: =10*K36 -> 2.8682144 | L38: =10*L36 -> 2.9986158 | ... N38: =10*N36 -> 3.1780637
C39: USD Simple | D39: Annual % | E39: =E8 -> 0.1 | F39: =E39 -> 0.1 | G39: =F39 -> 0.1 | H39: =G39 -> 0.1 | I39: =H39 -> 0.1 | J39: =I39 -> 0.1 | K39: =J39 -> 0.1 | L39: =K39 -> 0.1 | M39: =L39 -> 0.1 | N39: =M39 -> 0.1
D40: Test Case Annual | E40: =E37*E$15 -> 100000 | F40: =F37*F$15 -> 100000 | G40: =G37*G$15 -> 100000 | H40: =H37*H$15 -> 100000 | I40: =I37*I$15 -> 100000 | J40: =J37*J$15 -> 100000 | K40: =K37*K$15 -> 100000 | L40: =L37*L$15 -> 100000 | ... N40: =N37*N$15 -> 100000
D41: Test Case Cumulative | E41: =E40 -> 100000 | F41: =E41+F40 -> 200000 | G41: =F41+G40 -> 300000 | H41: =G41+H40 -> 400000 | I41: =H41+I40 -> 500000 | J41: =I41+J40 -> 600000 | K41: =J41+K40 -> 700000 | L41: =K41+L40 -> 800000 | M41: =L41+M40 -> 900000 | N41: =M41+N40 -> 1000000
C42: USD Compounded | D42: Annual % | E42: =E36*E$15/$E$4 -> 0.1 | F42: =F36*F$15/$E$4-E42 -> 0.129 | G42: =G36*G$15/$E$4-F42-E42 -> 0.16641 | H42: =H36*H$15/$E$4-G42-F42-E42 -> 0.2146689 | I42: =I36*I$15/$E$4-H42-G42-F42-E42 -> 0.27692288 | J42: =J36*J$15/$E$4-I42-H42-G42-F42-E42 -> 0.35723052 | K42: =K36*K$15/$E$4-J42-I42-H42-G42-F42-E42 -> 0.46082737 | L42: =L36*L$15/$E$4-K42-J42-I42-H42-G42-F42-E42 -> 0.5944673 | M42: =M36*M$15/$E$4-L42-K42-J42-I42-H42-G42-F42-E42 -> 0.76686282 | N42: =N36*N$15/$E$4-M42-L42-K42-J42-I42-H42-G42-F42-E42 -> 0.98925304
D43: Annual Average % | I43: =AVERAGE(E42:I42) -> 0.17740036 | N43: =AVERAGE(E42:N42) -> 0.40556428
D44: Test Case Annual | E44: =E46 -> 100000 | F44: =F46-E46 -> 129000 | G44: =G46-F46 -> 166410 | H44: =H46-G46 -> 214668.9 | I44: =I46-H46 -> 276922.88 | J44: =J46-I46 -> 357230.52 | K44: =K46-J46 -> 460827.37 | L44: =L46-K46 -> 594467.3 | M44: =M46-L46 -> 766862.82 | N44: =N46-M46 -> 989253.04
D45: Test Case Annual Average | I45: =AVERAGE(E44:I44) -> 177400.36 | N45: =AVERAGE(E44:N44) -> 405564.28
...

Sheet 3X
B2: Bitcoin Lightning Credit Derivatives A permissionless, decentralized and distributed strategy for ultra-high yields using leveraged bitcoin growth and lightning transaction fee exposure | D2: Bitcoin Yield Estimate Variables BiGY = Bitcoin Growth Yield (CAGR) BiLY = Bitcoin Liquidity Yield BiTY = Bitcoin Transaction Yield | G2: Bitcoin Yield Estimate 5 Year Summary SR = Stable Receiver SB = Stable Balancer SP = Stable Provider | K2: Lightning Bank 5 Year Revenue Summary TVL = Total Value Locked
K3: Bitcoin TVL | L3: Measure | M3: BTC | N3: USD
D4: Bitcoin USD Price Start | E4: 100000 | G4: SR USD Comp. | H4: Annual Avg. % | I4: =I43 -> 0.17740036 | K4: =C127 -> 20000 | L4: Annual Avg. | M4: =I128 -> 413.83259 | N4: =M4*$I$15 -> 1.4783363e+08
D5: Annual Bitcoin Growth Yield % | E5: =SUMMARY!H6 -> 0.29 | G5: SP BiGY BTC | H5: Annual Avg. % | I5: =I67 -> 0.28802748 | K5: =C127 -> 20000 | L5: Cumulative | M5: =I129 -> 2069.163 | N5: =M5*$I$15 -> 7.3916815e+08
D6: Annual Bitcoin Liquidity Yield % | E6: =SUMMARY!L6 -> 0.02 | G6: SP BiLY BTC | H6: Annual Avg. % | I6: =I80 -> 0.049931982 | K6: =C130 -> 400000 | L6: Annual Avg. | M6: =I131 -> 8276.6518 | N6: =M6*$I$15 -> 2.9566726e+09
D7: Annual Bitcoin Transaction Yield % | E7: =SUMMARY!P6 -> 0.01 | G7: SP BiTY BTC | H7: Annual Avg. % | I7: =I95 -> 0.024965991 | K7: =C130 -> 400000 | L7: Cumulative | M7: =I132 -> 41383.259 | N7: =M7*$I$15 -> 1.4783363e+10
D8: Stable Receiver Security Annual USD % | E8: =SUMMARY!J21 -> 0.1 | G8: SP BiLY SR BTC | H8: Annual Avg. % | I8: =-I35 -> -0.049659911 | K8: =C133 -> 1000000 | L8: Annual Avg. | M8: =I134 -> 20691.63 | N8: =M8*$I$15 -> 7.3916815e+09
D9: Stable Balancer Security Annual USD % | E9: =SUMMARY!J22 -> 0.05 | G9: SP BiLY SB BTC | H9: Annual Avg. % | I9: =-I51 -> -0.062074889 | K9: =C133 -> 1000000 | L9: Cumulative | M9: =I135 -> 103458.15 | N9: =M9*$I$15 -> 3.6958408e+10
D10: Stable Balancer Debt Annual USD % | E10: =SUMMARY!J23 -> 0.075 | G10: SP Total BTC | H10: Annual Avg. % | I10: =I110 -> 0.25119066
D11: Stable Provider Debt-to-Value % | E11: =SUMMARY!J10 -> 1
B13: Yield Estimate Calculator | C13: Unit of Account | D13: Measure | E13: Year 1 | F13: Year 2 | G13: Year 3 | H13: Year 4 | I13: Year 5 | J13: Year 6 | K13: Year 7 | L13: Year 8 | M13: Year 9 | N13: Year 10
B15: Bitcoin | C15: USD | D15: Price | E15: =($E$4 * $E$5) + $E$4 -> 129000 | F15: =(E15 * $E$5) + E15 -> 166410 | G15: =(F15 * $E$5) + F15 -> 214668.9 | H15: =(G15 * $E$5) + G15 -> 276922.88 | I15: =(H15 * $E$5) + H15 -> 357230.52 | J15: =(I15 * $E$5) + I15 -> 460827.37 | K15: =(J15 * $E$5) + J15 -> 594467.3 | L15: =(K15 * $E$5) + K15 -> 766862.82 | M15: =(L15 * $E$5) + L15 -> 989253.04 | N15: =(M15 * $E$5) + M15 -> 1276136.4
D16: Marketcap | E16: =E15*21000000 -> 2709000000000 | F16: =F15*21000000 -> 3494610000000 | G16: =G15*21000000 -> 4508046900000 | H16: =H15*21000000 -> 5815380501000 | I16: =I15*21000000 -> 7.5018408e+12 | J16: =J15*21000000 -> 9.6773747e+12 | K16: =K15*21000000 -> 1.2483813e+13 | L16: =L15*21000000 -> 1.6104119e+13 | ... N16: =N15*21000000 -> 2.6798865e+13
B17: Bitcoin Growth Yield (BiGY) | C17: BTC | D17: Stable Security Cumulative % | E17: =(E15-$E4)/E15 -> 0.2248062 | F17: =(F15-$E4)/F15 -> 0.39907457 | G17: =(G15-$E4)/G15 -> 0.53416634 | H17: =(H15-$E4)/H15 -> 0.63888863 | I17: =(I15-$E4)/I15 -> 0.72006871 | J17: =(J15-$E4)/J15 -> 0.782999 | K17: =(K15-$E4)/K15 -> 0.83178217 | L17: =(L15-$E4)/L15 -> 0.86959858 | ... N17: =(N15-$E4)/N15 -> 0.92163847
D18: Stable Security Remaining % | E18: =1-E17 -> 0.7751938 | F18: =1-F17 -> 0.60092543 | G18: =1-G17 -> 0.46583366 | H18: =1-H17 -> 0.36111137 | I18: =1-I17 -> 0.27993129 | J18: =1-J17 -> 0.217001 | K18: =1-K17 -> 0.16821783 | L18: =1-L17 -> 0.13040142 | ... N18: =1-N17 -> 0.078361528
D19: Stable Security Annual % | E19: =E17 -> 0.2248062 | F19: =F17-E17 -> 0.17426837 | G19: =G17-F17 -> 0.13509176 | H19: =H17-G17 -> 0.1047223 | I19: =I17-H17 -> 0.081180075 | J19: =J17-I17 -> 0.06293029 | K19: =K17-J17 -> 0.048783171 | L19: =L17-K17 -> 0.037816412 | M19: =M17-L17 -> 0.029315048 | N19: =N17-M17 -> 0.022724843
D20: Stable Security Annual Average % | I20: =AVERAGE(E19:I19) -> 0.14401374 | N20: =AVERAGE(E19:N19) -> 0.092163847
D21: Stable Debt Annual % | E21: =$E$11*E19 -> 0.2248062 | F21: =$E$11*F19 -> 0.17426837 | G21: =$E$11*G19 -> 0.13509176 | H21: =$E$11*H19 -> 0.1047223 | I21: =$E$11*I19 -> 0.081180075 | J21: =$E$11*J19 -> 0.06293029 | K21: =$E$11*K19 -> 0.048783171 | L21: =$E$11*L19 -> 0.037816412 | ... N21: =$E$11*N19 -> 0.022724843
D22: Stable Debt Annual Avg. % | I22: =AVERAGE(E21:I21) -> 0.14401374 | N22: =AVERAGE(E21:N21) -> 0.092163847
D23: Total Annual % | E23: =E19+E21 -> 0.4496124 | F23: =F19+F21 -> 0.34853675 | G23: =G19+G21 -> 0.27018352 | H23: =H19+H21 -> 0.20944459 | I23: =I19+I21 -> 0.16236015 | J23: =J19+J21 -> 0.12586058 | K23: =K19+K21 -> 0.097566342 | L23: =L19+L21 -> 0.075632823 | ... N23: =N19+N21 -> 0.045449686
D24: Total Annual Average % | I24: =AVERAGE(E23:I23) -> 0.28802748 | N24: =AVERAGE(E23:N23) -> 0.18432769
B25: Bitcoin Liquidity Yield (BiLY) | C25: BTC | D25: Annual % | E25: =((1+$E$11)*$E$6)+($E$6*E18) -> 0.055503876 | F25: =((1+$E$11)*$E$6)+($E$6*F18) -> 0.052018509 | G25: =((1+$E$11)*$E$6)+($E$6*G18) -> 0.049316673 | H25: =((1+$E$11)*$E$6)+($E$6*H18) -> 0.047222227 | I25: =((1+$E$11)*$E$6)+($E$6*I18) -> 0.045598626 | J25: =((1+$E$11)*$E$6)+($E$6*J18) -> 0.04434002 | K25: =((1+$E$11)*$E$6)+($E$6*K18) -> 0.043364357 | L25: =((1+$E$11)*$E$6)+($E$6*L18) -> 0.042608028 | ... N25: =((1+$E$11)*$E$6)+($E$6*N18) -> 0.041567231
D26: Annual Average % | I26: =AVERAGE(E25:I25) -> 0.049931982 | N26: =AVERAGE(E25:N25) -> 0.046356127
D27: Cumulative % | E27: =E25 -> 0.055503876 | F27: =E27+F25 -> 0.10752238 | G27: =F27+G25 -> 0.15683906 | H27: =G27+H25 -> 0.20406129 | I27: =H27+I25 -> 0.24965991 | J27: =I27+J25 -> 0.29399993 | K27: =J27+K25 -> 0.33736429 | L27: =K27+L25 -> 0.37997232 | M27: =L27+M25 -> 0.42199404 | N27: =M27+N25 -> 0.46356127
B28: Bitcoin Transaction Yield (BiTY) | C28: BTC | D28: Annual % | E28: =((1+$E$11)*$E$7)+($E$7*E18) -> 0.027751938 | F28: =((1+$E$11)*$E$7)+($E$7*F18) -> 0.026009254 | G28: =((1+$E$11)*$E$7)+($E$7*G18) -> 0.024658337 | H28: =((1+$E$11)*$E$7)+($E$7*H18) -> 0.023611114 | I28: =((1+$E$11)*$E$7)+($E$7*I18) -> 0.022799313 | J28: =((1+$E$11)*$E$7)+($E$7*J18) -> 0.02217001 | K28: =((1+$E$11)*$E$7)+($E$7*K18) -> 0.021682178 | L28: =((1+$E$11)*$E$7)+($E$7*L18) -> 0.021304014 | ... N28: =((1+$E$11)*$E$7)+($E$7*N18) -> 0.020783615
D29: Annual Average % | I29: =AVERAGE(E28:I28) -> 0.024965991 | N29: =AVERAGE(E28:N28) -> 0.023178064
